Workbook
Name JR_PAGE_ANCHOR_0_1: 'Rincian Pesanan Penjualan'!$A$1
Name Slicer_Brand: #N/A
Name Slicer_Divisi: #N/A
Name Slicer_Promo_ID: #N/A
Name Slicer_SALES: #N/A
Name Slicer_Tanggal: #N/A

Sheet DATA MASTER
A1: No. | B1: Brand | C1: Description | D1: Divisi | E1: Kemasan | F1: Gross Weight | G1: Coli Qty. | H1: Base Unit of Measure | I1: Price RTL | J1: sellprice | K1: Price RTL (2025) | L1: sellprice( 2025) | M1: Price RTL ( Agus 2025) | N1: sellprice( Agus 2025) | O1: Price RTL ( April 2026) | P1: sellprice( April 2026) | Q1: Price RTL ( Mei 2026) | R1: sellprice(Mei 2026)
A2: ABEM001K701 | B2: =LEFT(A2,7) -> ABEM001 | C2: ARIES BLING 701 1 KG | D2: DIV 1 | E2: 1 KG | F2: 1.05 | G2: 24 | H2: DS | O2: 28000 | P2: 31900 | Q2: 29400 | R2: 33400
A3: ABEM001K702 | B3: =LEFT(A3,7) -> ABEM001 | C3: ARIES BLING 702 1 KG | D3: DIV 1 | E3: 1 KG | F3: 1.05 | G3: 24 | H3: DS | O3: 28000 | P3: 31900 | Q3: 29400 | R3: 33400
A4: ABEM001K703 | B4: =LEFT(A4,7) -> ABEM001 | C4: ARIES BLING 703 1 KG | D4: DIV 1 | E4: 1 KG | F4: 1.05 | G4: 24 | H4: DS | O4: 28000 | P4: 31900 | Q4: 29400 | R4: 33400
A5: ABEM001K704 | B5: =LEFT(A5,7) -> ABEM001 | C5: ARIES BLING 704 1 KG | D5: DIV 1 | E5: 1 KG | F5: 1.05 | G5: 24 | H5: DS | O5: 28000 | P5: 31900 | Q5: 29400 | R5: 33400
A6: ABEM001K705 | B6: =LEFT(A6,7) -> ABEM001 | C6: ARIES BLING 705 1 KG | D6: DIV 1 | E6: 1 KG | F6: 1.05 | G6: 24 | H6: DS | O6: 28000 | P6: 31900 | Q6: 29400 | R6: 33400
A7: ABEM001K706 | B7: =LEFT(A7,7) -> ABEM001 | C7: ARIES BLING 706 1 KG | D7: DIV 1 | E7: 1 KG | F7: 1.05 | G7: 24 | H7: DS | O7: 28000 | P7: 31900 | Q7: 29400 | R7: 33400
A8: ABEM001K707 | B8: =LEFT(A8,7) -> ABEM001 | C8: ARIES BLING 707 1 KG | D8: DIV 1 | E8: 1 KG | F8: 1.05 | G8: 24 | H8: DS | O8: 28000 | P8: 31900 | Q8: 29400 | R8: 33400
A9: ABEM001K708 | B9: =LEFT(A9,7) -> ABEM001 | C9: ARIES BLING 708 1 KG | D9: DIV 1 | E9: 1 KG | F9: 1.05 | G9: 24 | H9: DS | O9: 28000 | P9: 31900 | Q9: 29400 | R9: 33400
A10: ABEM001K709 | B10: =LEFT(A10,7) -> ABEM001 | C10: ARIES BLING 709 1 KG | D10: DIV 1 | E10: 1 KG | F10: 1.05 | G10: 24 | H10: DS | O10: 28000 | P10: 31900 | Q10: 29400 | R10: 33400
A11: ABEM001K710 | B11: =LEFT(A11,7) -> ABEM001 | C11: ARIES BLING 710 1 KG | D11: DIV 1 | E11: 1 KG | F11: 1.05 | G11: 24 | H11: DS | O11: 28000 | P11: 31900 | Q11: 29400 | R11: 33400
A12: ABEM001K711 | B12: =LEFT(A12,7) -> ABEM001 | C12: ARIES BLING 711 1 KG | D12: DIV 1 | E12: 1 KG | F12: 1.05 | G12: 24 | H12: DS | O12: 28000 | P12: 31900 | Q12: 29400 | R12: 33400
A13: ABEM001K712 | B13: =LEFT(A13,7) -> ABEM001 | C13: ARIES BLING 712 1 KG | D13: DIV 1 | E13: 1 KG | F13: 1.05 | G13: 24 | H13: DS | O13: 28000 | P13: 31900 | Q13: 29400 | R13: 33400
... A25: ABEM001K724 | B25: =LEFT(A25,7) -> ABEM001 | C25: ARIES BLING 724 1 KG | D25: DIV 1 | E25: 1 KG | F25: 1.05 | G25: 24 | H25: DS | O25: 28000 | P25: 31900 | Q25: 29400 | R25: 33400
A26: ABEM001K725 | B26: ABEM001K725 | C26: ARIES BLING 725 1 KG | D26: DIV 1 | E26: 1 KG | F26: 1.05 | G26: 24 | H26: DS | O26: 28000 | P26: 31900 | Q26: 29400 | R26: 33400
A27: ABEM001K726 | B27: =LEFT(A27,7) -> ABEM001 | C27: ARIES BLING 726 1 KG | D27: DIV 1 | E27: 1 KG | F27: 1.05 | G27: 24 | H27: DS | O27: 28000 | P27: 31900 | Q27: 29400 | R27: 33400
A28: ABEM001KBA | B28: ABEM001KBA | C28: Aries Bling Emulsion Base A 1 Kg | D28: MTAB | E28: 1 KG | F28: 1.05 | G28: 24 | H28: DS | O28: 28000 | P28: 30100 | Q28: 29400 | R28: 31500
A29: ABEM001KBC | B29: ABEM001KBC | C29: Aries Bling Emulsion Base C 1 Kg | D29: MTAB | E29: 1 KG | F29: 1.05 | G29: 24 | H29: DS | O29: 25800 | P29: 27900 | Q29: 27000 | R29: 29100
A30: ABEM001KSB | B30: =LEFT(A30,7) -> ABEM001 | C30: ARIES BLING SB 1 KG | D30: DIV 1 | E30: 1 KG | F30: 1.05 | G30: 24 | H30: DS | O30: 28000 | P30: 31900 | Q30: 29400 | R30: 33400
A31: ABEM001KSW | B31: ABEM001KSW | C31: Aries Bling Emulsion SW 1 Kg | D31: DIV 1 | E31: 1 KG | F31: 1.05 | G31: 24 | H31: DS | O31: 28000 | P31: 31900 | Q31: 29400 | R31: 33400
A32: ABEM005K701 | B32: =LEFT(A32,7) -> ABEM005 | C32: Aries Bling Emulsion 701 | D32: DIV 2 | E32: 4.5 KG | F32: 4.74 | G32: 4 | H32: DS | I32: 65300 | J32: 79900 | K32: 67600 | L32: 82400 | M32: 69000 | N32: 82400 | O32: 80000 | P32: 94700 | Q32: 84000 | R32: 99000
A33: ABEM005K702 | B33: =LEFT(A33,7) -> ABEM005 | C33: Aries Bling Emulsion 702 | D33: DIV 2 | E33: 4.5 KG | F33: 4.74 | G33: 4 | H33: DS | I33: 65300 | J33: 79900 | K33: 67600 | L33: 82400 | M33: 69000 | N33: 82400 | O33: 80000 | P33: 94700 | Q33: 84000 | R33: 99000
A34: ABEM005K703 | B34: =LEFT(A34,7) -> ABEM005 | C34: Aries Bling Emulsion 703 | D34: DIV 2 | E34: 4.5 KG | F34: 4.74 | G34: 4 | H34: DS | I34: 65300 | J34: 79900 | K34: 67600 | L34: 82400 | M34: 69000 | N34: 82400 | O34: 80000 | P34: 94700 | Q34: 84000 | R34: 99000
A35: ABEM005K704 | B35: =LEFT(A35,7) -> ABEM005 | C35: Aries Bling Emulsion 704 | D35: DIV 2 | E35: 4.5 KG | F35: 4.74 | G35: 4 | H35: DS | I35: 65300 | J35: 79900 | K35: 67600 | L35: 82400 | M35: 69000 | N35: 82400 | O35: 80000 | P35: 94700 | Q35: 84000 | R35: 99000
A36: ABEM005K705 | B36: =LEFT(A36,7) -> ABEM005 | C36: Aries Bling Emulsion 705 | D36: DIV 2 | E36: 4.5 KG | F36: 4.74 | G36: 4 | H36: DS | I36: 65300 | J36: 79900 | K36: 67600 | L36: 82400 | M36: 69000 | N36: 82400 | O36: 80000 | P36: 94700 | Q36: 84000 | R36: 99000
A37: ABEM005K706 | B37: =LEFT(A37,7) -> ABEM005 | C37: Aries Bling Emulsion 706 | D37: DIV 2 | E37: 4.5 KG | F37: 4.74 | G37: 4 | H37: DS | I37: 65300 | J37: 79900 | K37: 67600 | L37: 82400 | M37: 69000 | N37: 82400 | O37: 80000 | P37: 94700 | Q37: 84000 | R37: 99000
A38: ABEM005K707 | B38: =LEFT(A38,7) -> ABEM005 | C38: Aries Bling Emulsion 707 | D38: DIV 2 | E38: 4.5 KG | F38: 4.74 | G38: 4 | H38: DS | I38: 65300 | J38: 79900 | K38: 67600 | L38: 82400 | M38: 69000 | N38: 82400 | O38: 80000 | P38: 94700 | Q38: 84000 | R38: 99000
A39: ABEM005K708 | B39: =LEFT(A39,7) -> ABEM005 | C39: Aries Bling Emulsion 708 | D39: DIV 2 | E39: 4.5 KG | F39: 4.74 | G39: 4 | H39: DS | I39: 65300 | J39: 79900 | K39: 67600 | L39: 82400 | M39: 69000 | N39: 82400 | O39: 80000 | P39: 94700 | Q39: 84000 | R39: 99000
A40: ABEM005K709 | B40: =LEFT(A40,7) -> ABEM005 | C40: Aries Bling Emulsion 709 | D40: DIV 2 | E40: 4.5 KG | F40: 4.74 | G40: 4 | H40: DS | I40: 65300 | J40: 79900 | K40: 67600 | L40: 82400 | M40: 69000 | N40: 82400 | O40: 80000 | P40: 94700 | Q40: 84000 | R40: 99000
A41: ABEM005K710 | B41: =LEFT(A41,7) -> ABEM005 | C41: Aries Bling Emulsion 710 | D41: DIV 2 | E41: 4.5 KG | F41: 4.74 | G41: 4 | H41: DS | I41: 65300 | J41: 79900 | K41: 67600 | L41: 82400 | M41: 69000 | N41: 82400 | O41: 80000 | P41: 94700 | Q41: 84000 | R41: 99000
A42: ABEM005K711 | B42: =LEFT(A42,7) -> ABEM005 | C42: Aries Bling Emulsion 711 | D42: DIV 2 | E42: 4.5 KG | F42: 4.74 | G42: 4 | H42: DS | I42: 65300 | J42: 79900 | K42: 67600 | L42: 82400 | M42: 69000 | N42: 82400 | O42: 80000 | P42: 94700 | Q42: 84000 | R42: 99000
A43: ABEM005K712 | B43: =LEFT(A43,7) -> ABEM005 | C43: Aries Bling Emulsion 712 | D43: DIV 2 | E43: 4.5 KG | F43: 4.74 | G43: 4 | H43: DS | I43: 65300 | J43: 79900 | K43: 67600 | L43: 82400 | M43: 69000 | N43: 82400 | O43: 80000 | P43: 94700 | Q43: 84000 | R43: 99000
... A55: ABEM005K724 | B55: =LEFT(A55,7) -> ABEM005 | C55: Aries Bling Emulsion 724 | D55: DIV 2 | E55: 4.5 KG | F55: 4.74 | G55: 4 | H55: DS | I55: 65300 | J55: 79900 | K55: 67600 | L55: 82400 | M55: 69000 | N55: 82400 | O55: 80000 | P55: 94700 | Q55: 84000 | R55: 99000
A56: ABEM005K725 | B56: ABEM005K725 | C56: Aries Bling Emulsion 725 | D56: DIV 2 | E56: 4.5 KG | F56: 4.74 | G56: 4 | H56: DS | I56: 65300 | J56: 79900 | K56: 67600 | L56: 82400 | M56: 69000 | N56: 82400 | O56: 80000 | P56: 94700 | Q56: 84000 | R56: 99000
A57: ABEM005K726 | B57: =LEFT(A57,7) -> ABEM005 | C57: Aries Bling Emulsion 726 | D57: DIV 2 | E57: 4.5 KG | F57: 4.74 | G57: 4 | H57: DS | I57: 65300 | J57: 79900 | K57: 67600 | L57: 82400 | M57: 69000 | N57: 82400 | O57: 80000 | P57: 94700 | Q57: 84000 | R57: 99000
A58: ABEM005KSB | B58: =LEFT(A58,7) -> ABEM005 | C58: Aries Bling Emulsion SB | D58: DIV 2 | E58: 4.5 KG | F58: 4.74 | G58: 4 | H58: DS | I58: 65300 | J58: 79900 | K58: 67600 | L58: 82400 | M58: 69000 | N58: 82400 | O58: 80000 | P58: 94700 | Q58: 84000 | R58: 99000
A59: ABEM005KSW | B59: ABEM005KSW | C59: Aries Bling Emulsion SW | D59: DIV 2 | E59: 4.5 KG | F59: 4.74 | G59: 4 | H59: DS | I59: 65300 | J59: 79900 | K59: 67600 | L59: 82400 | M59: 69000 | N59: 82400 | O59: 80000 | P59: 94700 | Q59: 84000 | R59: 99000
A60: ABEM005KBA | B60: ABEM005KBA | C60: Aries Bling Emulsion Base A 5 Kg | D60: MTAB | E60: 4 KG | F60: 4.13 | G60: 4 | H60: DS | O60: 80000 | P60: 89600 | Q60: 84000 | R60: 93600
A61: ABEM005KBC | B61: ABEM005KBC | C61: Aries Bling Emulsion Base C 5 Kg | D61: MTAB | E61: 4 KG | F61: 4.13 | G61: 4 | H61: DS | O61: 73600 | P61: 83200 | Q61: 77300 | R61: 86900
A62: ABEM020KP701 | B62: =LEFT(A62,7) -> ABEM020 | C62: Aries Bling Emulsion 701 | D62: DIV 2 | E62: 20 KG | F62: 19.01 | G62: 1 | H62: PL | I62: 251000 | J62: 308300 | K62: 259800 | L62: 317800 | M62: 265000 | N62: 317800 | O62: 307400 | P62: 365300 | Q62: 322800 | R62: 381600
...

Sheet Margin Calculation
AF2: Margin | AG2: =SUM(T:T) -> 3.9276956e+08
AF3: Expdc | AG3: =SUM(U:U) -> 45462434
B4: NAMA TOKO | K4: Margin Promo Juli | AF4: Upah Buruh | AG4: =SUM(V:V) -> 4235630.5
B5: TARGET | K5: =SUM(R:R)*1.11 -> 2.610796e+09 | AF5: Margin Kotor | AG5: =AG2-AG3-AG4 -> 3.4307149e+08
AF6: Reward | AG6: =SUM(AD:AD)+SUM(AC:AC)+SUM(AA:AA) -> #REF!
A7: No | B7: Tanggal | C7: Nomor Faktur | D7: SALES | E7: Brand | F7: Divisi | G7: Kuantitas | H7: Coli Qty. | I7: GrossWeight | J7: Harga Jual April 2026 | K7: Harga Beli April 2026 | L7: SD | M7: BD | N7: Diskon Promo Faktur | O7: Diskon Faktur | P7: Reward hadiah | Q7: Keterangan | R7: HJ Total | S7: HB Total | T7: Margin | U7: EXPDC | V7: Upah Buruh | W7: TW 2% | X7: Margin | Y7: Buffer hadiah | Z7: Cashback kontrak | AA7: Cashback | AB7: Biaya angkut ekspedisi | AC7: CB Kontrak | AD7: Potongan gathering | AF7: TW 2% | AG7: =SUM(W:W) -> 47299145
A8: 1 | B8: 46235 | C8: SO.AV.2026.08.00001 | D8: SALES002 | E8: ABEM005 | F8: =IFERROR(VLOOKUP(E8,'DATA MASTER'!$B$1:$R$3858,3,0),"") -> DIV 2 | G8: 2 | H8: =IFERROR(VLOOKUP(E8,'DATA MASTER'!$B$1:$R$3858,6,0),"") -> 4 | I8: =IFERROR(VLOOKUP(E8,'DATA MASTER'!$B$1:$R$3858,5,0),"") -> 4.74 | J8: =IFERROR(VLOOKUP(E8,'DATA MASTER'!$B$1:$R$3858,17,0),"") -> 99000 | K8: =IFERROR(VLOOKUP(E8,'DATA MASTER'!$B$1:$R$3858,16,0),"") -> 84000 | L8: =IFERROR(IF(F8="MTAB",12.5%*J8,7.5%*J8),"") -> 7425 | M8: =IFERROR(IF(F8="MTAB",19.011%*K8,14.488%*K8),"") -> 12169.92 | N8: 0 | O8: 0 | R8: =IFERROR((((J8-L8)/1.11*(100-O8)%*G8)-(ROUNDDOWN(G8/Y8,0)*N8)),"") -> 165000 | S8: =IFERROR((K8-M8)/1.11*(100-O8)%*G8,"") -> 129423.57 | T8: =IFERROR(R8-S8,"") -> 35576.432 | U8: =IFERROR(I8*G8*700,"") -> 6636 | V8: =IFERROR(G8*I8/23000*1500000,"") -> 618.26087 | W8: =IFERROR(2%*R8*1.11,"") -> 3663 | X8: =IFERROR(T8-U8-V8-W8-Z8-AC8-AB8-AA8-AD8,"") -> 21534.172 | Y8: 1 | Z8: 0 | AA8: =IFERROR(ROUNDDOWN(G8/Y8,0)*P8,"") -> 0 | AB8: =IFERROR(IF(OR(D8="SALES008",D8="SALES010"),IF(MOD(G8,H8)=0,10000*G8/H8,10000*(ROUNDUP(G8/H8,0))),0),"") -> 0 | AC8: 0 | AD8: 3125 | AF8: Laba Bersih | AG8: =AG5-AG6-AG7 -> #REF!
A9: 2 | B9: 46235 | C9: SO.AV.2026.08.00002 | D9: SALES005 | E9: AVSY100 | F9: =IFERROR(VLOOKUP(E9,'DATA MASTER'!$B$1:$R$3858,3,0),"") -> DIV 1 | G9: 24 | H9: =IFERROR(VLOOKUP(E9,'DATA MASTER'!$B$1:$R$3858,6,0),"") -> 120 | I9: =IFERROR(VLOOKUP(E9,'DATA MASTER'!$B$1:$R$3858,5,0),"") -> 0.145 | J9: =IFERROR(VLOOKUP(E9,'DATA MASTER'!$B$1:$R$3858,17,0),"") -> 15108.333 | K9: =IFERROR(VLOOKUP(E9,'DATA MASTER'!$B$1:$R$3858,16,0),"") -> 14025 | L9: =IFERROR(IF(F9="MTAB",12.5%*J9,7.5%*J9),"") -> 1133.125 | M9: =IFERROR(IF(F9="MTAB",19.011%*K9,14.488%*K9),"") -> 2031.942 | N9: 0 | O9: 0 | R9: =IFERROR((((J9-L9)/1.11*(100-O9)%*G9)-(ROUNDDOWN(G9/Y9,0)*N9)),"") -> 302166.67 | S9: =IFERROR((K9-M9)/1.11*(100-O9)%*G9,"") -> 259309.36 | T9: =IFERROR(R9-S9,"") -> 42857.305 | U9: =IFERROR(I9*G9*700,"") -> 2436 | V9: =IFERROR(G9*I9/23000*1500000,"") -> 226.95652 | W9: =IFERROR(2%*R9*1.11,"") -> 6708.1 | X9: =IFERROR(T9-U9-V9-W9-Z9-AC9-AB9-AA9-AD9,"") -> 33486.248 | Y9: 1 | Z9: 0 | AA9: =IFERROR(ROUNDDOWN(G9/Y9,0)*P9,"") -> 0 | AB9: =IFERROR(IF(OR(D9="SALES008",D9="SALES010"),IF(MOD(G9,H9)=0,10000*G9/H9,10000*(ROUNDUP(G9/H9,0))),0),"") -> 0 | AC9: 0 | AD9: 0 | AF9: BIAYA ANGKUT | AG9: =SUM(AB:AB) -> 3730000
A10: 3 | B10: 46235 | C10: SO.AV.2026.08.00002 | D10: SALES005 | E10: AVSY200 | F10: =IFERROR(VLOOKUP(E10,'DATA MASTER'!$B$1:$R$3858,3,0),"") -> DIV 1 | G10: 36 | H10: =IFERROR(VLOOKUP(E10,'DATA MASTER'!$B$1:$R$3858,6,0),"") -> 72 | I10: =IFERROR(VLOOKUP(E10,'DATA MASTER'!$B$1:$R$3858,5,0),"") -> 0.245333 | J10: =IFERROR(VLOOKUP(E10,'DATA MASTER'!$B$1:$R$3858,17,0),"") -> 27908.333 | K10: =IFERROR(VLOOKUP(E10,'DATA MASTER'!$B$1:$R$3858,16,0),"") -> 25850 | L10: =IFERROR(IF(F10="MTAB",12.5%*J10,7.5%*J10),"") -> 2093.125 | M10: =IFERROR(IF(F10="MTAB",19.011%*K10,14.488%*K10),"") -> 3745.148 | N10: 0 | O10: 0 | R10: =IFERROR((((J10-L10)/1.11*(100-O10)%*G10)-(ROUNDDOWN(G10/Y10,0)*N10)),"") -> 837250 | S10: =IFERROR((K10-M10)/1.11*(100-O10)%*G10,"") -> 716914.12 | T10: =IFERROR(R10-S10,"") -> 120335.88 | U10: =IFERROR(I10*G10*700,"") -> 6182.3916 | V10: =IFERROR(G10*I10/23000*1500000,"") -> 575.99922 | W10: =IFERROR(2%*R10*1.11,"") -> 18586.95 | X10: =IFERROR(T10-U10-V10-W10-Z10-AC10-AB10-AA10-AD10,"") -> 94990.54 | Y10: 1 | Z10: 0 | AA10: =IFERROR(ROUNDDOWN(G10/Y10,0)*P10,"") -> 0 | AB10: =IFERROR(IF(OR(D10="SALES008",D10="SALES010"),IF(MOD(G10,H10)=0,10000*G10/H10,10000*(ROUNDUP(G10/H10,0))),0),"") -> 0 | AC10: 0 | AD10: 0 | AF10: Margin total | AG10: =AG8-AG9 -> #REF!
A11: 4 | B11: 46235 | C11: SO.AV.2026.08.00003 | D11: SALES001 | E11: AVSY001 | F11: =IFERROR(VLOOKUP(E11,'DATA MASTER'!$B$1:$R$3858,3,0),"") -> DIV 1 | G11: 6 | H11: =IFERROR(VLOOKUP(E11,'DATA MASTER'!$B$1:$R$3858,6,0),"") -> 24 | I11: =IFERROR(VLOOKUP(E11,'DATA MASTER'!$B$1:$R$3858,5,0),"") -> 1.23 | J11: =IFERROR(VLOOKUP(E11,'DATA MASTER'!$B$1:$R$3858,17,0),"") -> 99800 | K11: =IFERROR(VLOOKUP(E11,'DATA MASTER'!$B$1:$R$3858,16,0),"") -> 92100 | L11: =IFERROR(IF(F11="MTAB",12.5%*J11,7.5%*J11),"") -> 7485 | M11: =IFERROR(IF(F11="MTAB",19.011%*K11,14.488%*K11),"") -> 13343.448 | N11: 0 | O11: 0 | R11: =IFERROR((((J11-L11)/1.11*(100-O11)%*G11)-(ROUNDDOWN(G11/Y11,0)*N11)),"") -> 499000 | S11: =IFERROR((K11-M11)/1.11*(100-O11)%*G11,"") -> 425711.09 | T11: =IFERROR(R11-S11,"") -> 73288.908 | U11: =IFERROR(I11*G11*700,"") -> 5166 | V11: =IFERROR(G11*I11/23000*1500000,"") -> 481.30435 | W11: =IFERROR(2%*R11*1.11,"") -> 11077.8 | X11: =IFERROR(T11-U11-V11-W11-Z11-AC11-AB11-AA11-AD11,"") -> 48230.47 | Y11: 1 | Z11: 0 | AA11: =IFERROR(ROUNDDOWN(G11/Y11,0)*P11,"") -> 0 | AB11: =IFERROR(IF(OR(D11="SALES008",D11="SALES010"),IF(MOD(G11,H11)=0,10000*G11/H11,10000*(ROUNDUP(G11/H11,0))),0),"") -> 0 | AC11: 0 | AD11: 8333.3333 | AF11: Emas
A12: 5 | B12: 46235 | C12: SO.AV.2026.08.00004 | D12: SALES012 | E12: AVSY001 | F12: =IFERROR(VLOOKUP(E12,'DATA MASTER'!$B$1:$R$3858,3,0),"") -> DIV 1 | G12: 5 | H12: =IFERROR(VLOOKUP(E12,'DATA MASTER'!$B$1:$R$3858,6,0),"") -> 24 | I12: =IFERROR(VLOOKUP(E12,'DATA MASTER'!$B$1:$R$3858,5,0),"") -> 1.23 | J12: =IFERROR(VLOOKUP(E12,'DATA MASTER'!$B$1:$R$3858,17,0),"") -> 99800 | K12: =IFERROR(VLOOKUP(E12,'DATA MASTER'!$B$1:$R$3858,16,0),"") -> 92100 | L12: =IFERROR(IF(F12="MTAB",12.5%*J12,7.5%*J12),"") -> 7485 | M12: =IFERROR(IF(F12="MTAB",19.011%*K12,14.488%*K12),"") -> 13343.448 | N12: 0 | O12: 0 | R12: =IFERROR((((J12-L12)/1.11*(100-O12)%*G12)-(ROUNDDOWN(G12/Y12,0)*N12)),"") -> 415833.33 | S12: =IFERROR((K12-M12)/1.11*(100-O12)%*G12,"") -> 354759.24 | T12: =IFERROR(R12-S12,"") -> 61074.09 | U12: =IFERROR(I12*G12*700,"") -> 4305 | V12: =IFERROR(G12*I12/23000*1500000,"") -> 401.08696 | W12: =IFERROR(2%*R12*1.11,"") -> 9231.5 | X12: =IFERROR(T12-U12-V12-W12-Z12-AC12-AB12-AA12-AD12,"") -> 39993.646 | Y12: =IF(E12="avem005",4,1) -> 1 | Z12: 0 | AA12: =IFERROR(ROUNDDOWN(G12/Y12,0)*P12,"") -> 0 | AB12: =IFERROR(IF(OR(D12="SALES008",D12="SALES010"),IF(MOD(G12,H12)=0,10000*G12/H12,10000*(ROUNDUP(G12/H12,0))),0),"") -> 0 | AC12: 0 | AD12: 7142.8571 | AF12: Total margin | AG12: =AG10+AG11 -> #REF!
A13: 6 | B13: 46235 | C13: SO.AV.2026.08.00006 | D13: SALES001 | E13: AVSY100 | F13: =IFERROR(VLOOKUP(E13,'DATA MASTER'!$B$1:$R$3858,3,0),"") -> DIV 1 | G13: 12 | H13: =IFERROR(VLOOKUP(E13,'DATA MASTER'!$B$1:$R$3858,6,0),"") -> 120 | I13: =IFERROR(VLOOKUP(E13,'DATA MASTER'!$B$1:$R$3858,5,0),"") -> 0.145 | J13: =IFERROR(VLOOKUP(E13,'DATA MASTER'!$B$1:$R$3858,17,0),"") -> 15108.333 | K13: =IFERROR(VLOOKUP(E13,'DATA MASTER'!$B$1:$R$3858,16,0),"") -> 14025 | L13: =IFERROR(IF(F13="MTAB",12.5%*J13,7.5%*J13),"") -> 1133.125 | M13: =IFERROR(IF(F13="MTAB",19.011%*K13,14.488%*K13),"") -> 2031.942 | N13: 0 | O13: 0 | R13: =IFERROR((((J13-L13)/1.11*(100-O13)%*G13)-(ROUNDDOWN(G13/Y13,0)*N13)),"") -> 151083.33 | S13: =IFERROR((K13-M13)/1.11*(100-O13)%*G13,"") -> 129654.68 | T13: =IFERROR(R13-S13,"") -> 21428.652 | U13: =IFERROR(I13*G13*700,"") -> 1218 | V13: =IFERROR(G13*I13/23000*1500000,"") -> 113.47826 | W13: =IFERROR(2%*R13*1.11,"") -> 3354.05 | X13: =IFERROR(T13-U13-V13-W13-Z13-AC13-AB13-AA13-AD13,"") -> 13409.791 | Y13: 1 | Z13: 0 | AA13: =IFERROR(ROUNDDOWN(G13/Y13,0)*P13,"") -> 0 | AB13: =IFERROR(IF(OR(D13="SALES008",D13="SALES010"),IF(MOD(G13,H13)=0,10000*G13/H13,10000*(ROUNDUP(G13/H13,0))),0),"") -> 0 | AC13: 0 | AD13: 3333.3333
A14: 7 | B14: 46235 | C14: SO.AV.2026.08.00006 | D14: SALES001 | E14: AVSY500 | F14: =IFERROR(VLOOKUP(E14,'DATA MASTER'!$B$1:$R$3858,3,0),"") -> DIV 1 | G14: 6 | H14: =IFERROR(VLOOKUP(E14,'DATA MASTER'!$B$1:$R$3858,6,0),"") -> 36 | I14: =IFERROR(VLOOKUP(E14,'DATA MASTER'!$B$1:$R$3858,5,0),"") -> 0.621 | J14: =IFERROR(VLOOKUP(E14,'DATA MASTER'!$B$1:$R$3858,17,0),"") -> 56900 | K14: =IFERROR(VLOOKUP(E14,'DATA MASTER'!$B$1:$R$3858,16,0),"") -> 52000 | L14: =IFERROR(IF(F14="MTAB",12.5%*J14,7.5%*J14),"") -> 4267.5 | M14: =IFERROR(IF(F14="MTAB",19.011%*K14,14.488%*K14),"") -> 7533.76 | N14: 0 | O14: 0 | R14: =IFERROR((((J14-L14)/1.11*(100-O14)%*G14)-(ROUNDDOWN(G14/Y14,0)*N14)),"") -> 284500 | S14: =IFERROR((K14-M14)/1.11*(100-O14)%*G14,"") -> 240358.05 | T14: =IFERROR(R14-S14,"") -> 44141.946 | U14: =IFERROR(I14*G14*700,"") -> 2608.2 | V14: =IFERROR(G14*I14/23000*1500000,"") -> 243 | W14: =IFERROR(2%*R14*1.11,"") -> 6315.9 | X14: =IFERROR(T14-U14-V14-W14-Z14-AC14-AB14-AA14-AD14,"") -> 31641.513 | Y14: 1 | Z14: 0 | AA14: =IFERROR(ROUNDDOWN(G14/Y14,0)*P14,"") -> 0 | AB14: =IFERROR(IF(OR(D14="SALES008",D14="SALES010"),IF(MOD(G14,H14)=0,10000*G14/H14,10000*(ROUNDUP(G14/H14,0))),0),"") -> 0 | AC14: 0 | AD14: 3333.3333
A15: 8 | B15: 46235 | C15: SO.AV.2026.08.00007 | D15: SALES004 | E15: AVSY001 | F15: =IFERROR(VLOOKUP(E15,'DATA MASTER'!$B$1:$R$3858,3,0),"") -> DIV 1 | G15: 6 | H15: =IFERROR(VLOOKUP(E15,'DATA MASTER'!$B$1:$R$3858,6,0),"") -> 24 | I15: =IFERROR(VLOOKUP(E15,'DATA MASTER'!$B$1:$R$3858,5,0),"") -> 1.23 | J15: =IFERROR(VLOOKUP(E15,'DATA MASTER'!$B$1:$R$3858,17,0),"") -> 99800 | K15: =IFERROR(VLOOKUP(E15,'DATA MASTER'!$B$1:$R$3858,16,0),"") -> 92100 | L15: =IFERROR(IF(F15="MTAB",12.5%*J15,7.5%*J15),"") -> 7485 | M15: =IFERROR(IF(F15="MTAB",19.011%*K15,14.488%*K15),"") -> 13343.448 | N15: 0 | O15: 0 | R15: =IFERROR((((J15-L15)/1.11*(100-O15)%*G15)-(ROUNDDOWN(G15/Y15,0)*N15)),"") -> 499000 | S15: =IFERROR((K15-M15)/1.11*(100-O15)%*G15,"") -> 425711.09 | T15: =IFERROR(R15-S15,"") -> 73288.908 | U15: =IFERROR(I15*G15*700,"") -> 5166 | V15: =IFERROR(G15*I15/23000*1500000,"") -> 481.30435 | W15: =IFERROR(2%*R15*1.11,"") -> 11077.8 | X15: =IFERROR(T15-U15-V15-W15-Z15-AC15-AB15-AA15-AD15,"") -> 56563.804 | Y15: 1 | Z15: 0 | AA15: =IFERROR(ROUNDDOWN(G15/Y15,0)*P15,"") -> 0 | AB15: =IFERROR(IF(OR(D15="SALES008",D15="SALES010"),IF(MOD(G15,H15)=0,10000*G15/H15,10000*(ROUNDUP(G15/H15,0))),0),"") -> 0 | AC15: 0 | AD15: 0 | AF15: Produk | AG15: Total Penjualan | AH15: Total margin | AI15: Persentase margin
A16: 9 | B16: 46235 | C16: SO.AV.2026.08.00008 | D16: SALES004 | E16: NODR001 | F16: =IFERROR(VLOOKUP(E16,'DATA MASTER'!$B$1:$R$3858,3,0),"") -> DIV 2 | G16: 2 | H16: =IFERROR(VLOOKUP(E16,'DATA MASTER'!$B$1:$R$3858,6,0),"") -> 24 | I16: =IFERROR(VLOOKUP(E16,'DATA MASTER'!$B$1:$R$3858,5,0),"") -> 1.09 | J16: =IFERROR(VLOOKUP(E16,'DATA MASTER'!$B$1:$R$3858,17,0),"") -> 82200 | K16: =IFERROR(VLOOKUP(E16,'DATA MASTER'!$B$1:$R$3858,16,0),"") -> 74900 | L16: =IFERROR(IF(F16="MTAB",12.5%*J16,7.5%*J16),"") -> 6165 | M16: =IFERROR(IF(F16="MTAB",19.011%*K16,14.488%*K16),"") -> 10851.512 | N16: 0 | O16: 0 | Q16: =VLOOKUP(#REF!,#REF!,1,0) -> #REF! | R16: =IFERROR((((J16-L16)/1.11*(100-O16)%*G16)-(ROUNDDOWN(G16/Y16,0)*N16)),"") -> 137000 | S16: =IFERROR((K16-M16)/1.11*(100-O16)%*G16,"") -> 115402.68 | T16: =IFERROR(R16-S16,"") -> 21597.319 | U16: =IFERROR(I16*G16*700,"") -> 1526 | V16: =IFERROR(G16*I16/23000*1500000,"") -> 142.17391 | W16: =IFERROR(2%*R16*1.11,"") -> 3041.4 | X16: =IFERROR(T16-U16-V16-W16-Z16-AC16-AB16-AA16-AD16,"") | Y16: 1 | Z16: =VLOOKUP(Q16,#REF!,4,0) -> #REF! | AA16: =IFERROR(ROUNDDOWN(G16/Y16,0)*P16,"") -> 0 | AB16: =IFERROR(IF(OR(D16="SALES008",D16="SALES010"),IF(MOD(G16,H16)=0,10000*G16/H16,10000*(ROUNDUP(G16/H16,0))),0),"") -> 0 | AC16: =Z16*R16*1.11 -> #REF! | AD16: 0 | AF16: ABEM001 | AG16: =SUMIF($E$8:$X$2162,AF16,$R$8:$R$2162)*1.11 -> 61790 | AH16: =SUMIF($E$8:$X$1048576,AF16,$X$8:$X$1048576) -> 3954.2329 | AI16: =AH16/AG16 -> 0.063994707
A17: 10 | B17: 46235 | C17: SO.AV.2026.08.00009 | D17: SALES005 | E17: YOSY001 | F17: =IFERROR(VLOOKUP(E17,'DATA MASTER'!$B$1:$R$3858,3,0),"") -> DIV 2 | G17: 18 | H17: =IFERROR(VLOOKUP(E17,'DATA MASTER'!$B$1:$R$3858,6,0),"") -> 24 | I17: =IFERROR(VLOOKUP(E17,'DATA MASTER'!$B$1:$R$3858,5,0),"") -> 0.85 | J17: =IFERROR(VLOOKUP(E17,'DATA MASTER'!$B$1:$R$3858,17,0),"") -> 74700 | K17: =IFERROR(VLOOKUP(E17,'DATA MASTER'!$B$1:$R$3858,16,0),"") -> 67900 | L17: =IFERROR(IF(F17="MTAB",12.5%*J17,7.5%*J17),"") -> 5602.5 | M17: =IFERROR(IF(F17="MTAB",19.011%*K17,14.488%*K17),"") -> 9837.352 | N17: 0 | O17: 0 | R17: =IFERROR((((J17-L17)/1.11*(100-O17)%*G17)-(ROUNDDOWN(G17/Y17,0)*N17)),"") -> 1120500 | S17: =IFERROR((K17-M17)/1.11*(100-O17)%*G17,"") -> 941556.45 | T17: =IFERROR(R17-S17,"") -> 178943.55 | U17: =IFERROR(I17*G17*700,"") -> 10710 | V17: =IFERROR(G17*I17/23000*1500000,"") -> 997.82609 | W17: =IFERROR(2%*R17*1.11,"") -> 24875.1 | X17: =IFERROR(T17-U17-V17-W17-Z17-AC17-AB17-AA17-AD17,"") -> 139419.44 | Y17: =IF(E17="avem005",4,1) -> 1 | Z17: 0 | AA17: =IFERROR(ROUNDDOWN(G17/Y17,0)*P17,"") -> 0 | AB17: =IFERROR(IF(OR(D17="SALES008",D17="SALES010"),IF(MOD(G17,H17)=0,10000*G17/H17,10000*(ROUNDUP(G17/H17,0))),0),"") -> 0 | AC17: 0 | AD17: 2941.1765 | AF17: ABEM001K725 | AG17: =SUMIF($E$8:$X$2162,AF17,$R$8:$R$2162)*1.11 -> 55611 | AH17: =SUMIF($E$8:$X$1048576,AF17,$X$8:$X$1048576) -> 3487.3997 | AI17: =AH17/AG17 -> 0.062710609
A18: 11 | B18: 46235 | C18: SO.AV.2026.08.00010 | D18: SALES001 | E18: AVGO005 | F18: =IFERROR(VLOOKUP(E18,'DATA MASTER'!$B$1:$R$3858,3,0),"") -> DIV 1 | G18: 2 | H18: =IFERROR(VLOOKUP(E18,'DATA MASTER'!$B$1:$R$3858,6,0),"") -> 4 | I18: =IFERROR(VLOOKUP(E18,'DATA MASTER'!$B$1:$R$3858,5,0),"") -> 5.23 | J18: =IFERROR(VLOOKUP(E18,'DATA MASTER'!$B$1:$R$3858,17,0),"") -> 231900 | K18: =IFERROR(VLOOKUP(E18,'DATA MASTER'!$B$1:$R$3858,16,0),"") -> 208700 | L18: =IFERROR(IF(F18="MTAB",12.5%*J18,7.5%*J18),"") -> 17392.5 | M18: =IFERROR(IF(F18="MTAB",19.011%*K18,14.488%*K18),"") -> 30236.456 | N18: 0 | O18: 0 | R18: =IFERROR((((J18-L18)/1.11*(100-O18)%*G18)-(ROUNDDOWN(G18/Y18,0)*N18)),"") -> 386500 | S18: =IFERROR((K18-M18)/1.11*(100-O18)%*G18,"") -> 321555.94 | T18: =IFERROR(R18-S18,"") -> 64944.065 | U18: =IFERROR(I18*G18*700,"") -> 7322 | V18: =IFERROR(G18*I18/23000*1500000,"") -> 682.17391 | W18: =IFERROR(2%*R18*1.11,"") -> 8580.3 | X18: =IFERROR(T18-U18-V18-W18-Z18-AC18-AB18-AA18-AD18,"") -> 38359.591 | Y18: =IF(E18="avem005",4,1) -> 1 | Z18: 0 | AA18: =IFERROR(ROUNDDOWN(G18/Y18,0)*P18,"") -> 0 | AB18: =IFERROR(IF(OR(D18="SALES008",D18="SALES010"),IF(MOD(G18,H18)=0,10000*G18/H18,10000*(ROUNDUP(G18/H18,0))),0),"") -> 0 | AC18: 0 | AD18: 10000 | AF18: ABEM001KSW | AG18: =SUMIF($E$8:$X$2162,AF18,$R$8:$R$2162)*1.11 -> 83416.5 | AH18: =SUMIF($E$8:$X$1048576,AF18,$X$8:$X$1048576) -> 6347.171 | AI18: =AH18/AG18 -> 0.076090114
A19: 12 | B19: 46235 | C19: SO.AV.2026.08.00011 | D19: SALES001 | E19: ABEM001 | F19: =IFERROR(VLOOKUP(E19,'DATA MASTER'!$B$1:$R$3858,3,0),"") -> DIV 1 | G19: 2 | H19: =IFERROR(VLOOKUP(E19,'DATA MASTER'!$B$1:$R$3858,6,0),"") -> 24 | I19: =IFERROR(VLOOKUP(E19,'DATA MASTER'!$B$1:$R$3858,5,0),"") -> 1.05 | J19: =IFERROR(VLOOKUP(E19,'DATA MASTER'!$B$1:$R$3858,17,0),"") -> 33400 | K19: =IFERROR(VLOOKUP(E19,'DATA MASTER'!$B$1:$R$3858,16,0),"") -> 29400 | L19: =IFERROR(IF(F19="MTAB",12.5%*J19,7.5%*J19),"") -> 2505 | M19: =IFERROR(IF(F19="MTAB",19.011%*K19,14.488%*K19),"") -> 4259.472 | N19: 0 | O19: 0 | R19: =IFERROR((((J19-L19)/1.11*(100-O19)%*G19)-(ROUNDDOWN(G19/Y19,0)*N19)),"") -> 55666.667 | S19: =IFERROR((K19-M19)/1.11*(100-O19)%*G19,"") -> 45298.249 | T19: =IFERROR(R19-S19,"") -> 10368.418 | U19: =IFERROR(I19*G19*700,"") -> 1470 | V19: =IFERROR(G19*I19/23000*1500000,"") -> 136.95652 | W19: =IFERROR(2%*R19*1.11,"") -> 1235.8 | X19: =IFERROR(T19-U19-V19-W19-Z19-AC19-AB19-AA19-AD19,"") -> 3954.2329 | Y19: 1 | Z19: 0 | AA19: =IFERROR(ROUNDDOWN(G19/Y19,0)*P19,"") -> 0 | AB19: =IFERROR(IF(OR(D19="SALES008",D19="SALES010"),IF(MOD(G19,H19)=0,10000*G19/H19,10000*(ROUNDUP(G19/H19,0))),0),"") -> 0 | AC19: 0 | AD19: 3571.4286 | AF19: ABEM005 | AG19: =SUMIF($E$8:$X$2162,AF19,$R$8:$R$2162)*1.11 -> 5036625 | AH19: =SUMIF($E$8:$X$1048576,AF19,$X$8:$X$1048576) -> 594555.79 | AI19: =AH19/AG19 -> 0.11804647
A20: 13 | B20: 46235 | C20: SO.AV.2026.08.00011 | D20: SALES001 | E20: ABEM005 | F20: =IFERROR(VLOOKUP(E20,'DATA MASTER'!$B$1:$R$3858,3,0),"") -> DIV 2 | G20: 2 | H20: =IFERROR(VLOOKUP(E20,'DATA MASTER'!$B$1:$R$3858,6,0),"") -> 4 | I20: =IFERROR(VLOOKUP(E20,'DATA MASTER'!$B$1:$R$3858,5,0),"") -> 4.74 | J20: =IFERROR(VLOOKUP(E20,'DATA MASTER'!$B$1:$R$3858,17,0),"") -> 99000 | K20: =IFERROR(VLOOKUP(E20,'DATA MASTER'!$B$1:$R$3858,16,0),"") -> 84000 | L20: =IFERROR(IF(F20="MTAB",12.5%*J20,7.5%*J20),"") -> 7425 | M20: =IFERROR(IF(F20="MTAB",19.011%*K20,14.488%*K20),"") -> 12169.92 | N20: 0 | O20: 0 | R20: =IFERROR((((J20-L20)/1.11*(100-O20)%*G20)-(ROUNDDOWN(G20/Y20,0)*N20)),"") -> 165000 | S20: =IFERROR((K20-M20)/1.11*(100-O20)%*G20,"") -> 129423.57 | T20: =IFERROR(R20-S20,"") -> 35576.432 | U20: =IFERROR(I20*G20*700,"") -> 6636 | V20: =IFERROR(G20*I20/23000*1500000,"") -> 618.26087 | W20: =IFERROR(2%*R20*1.11,"") -> 3663 | X20: =IFERROR(T20-U20-V20-W20-Z20-AC20-AB20-AA20-AD20,"") -> 21087.743 | Y20: 1 | Z20: 0 | AA20: =IFERROR(ROUNDDOWN(G20/Y20,0)*P20,"") -> 0 | AB20: =IFERROR(IF(OR(D20="SALES008",D20="SALES010"),IF(MOD(G20,H20)=0,10000*G20/H20,10000*(ROUNDUP(G20/H20,0))),0),"") -> 0 | AC20: 0 | AD20: 3571.4286 | AF20: ABEM005K725 | AG20: =SUMIF($E$8:$X$2162,AF20,$R$8:$R$2162)*1.11 -> 659340 | AH20: =SUMIF($E$8:$X$1048576,AF20,$X$8:$X$1048576) -> 80871.313 | AI20: =AH20/AG20 -> 0.12265495
A21: 14 | B21: 46235 | C21: SO.AV.2026.08.00012 | D21: SALES012 | E21: AVEM005 | F21: =IFERROR(VLOOKUP(E21,'DATA MASTER'!$B$1:$R$3858,3,0),"") -> DIV 1 | G21: 4 | H21: =IFERROR(VLOOKUP(E21,'DATA MASTER'!$B$1:$R$3858,6,0),"") -> 4 | I21: =IFERROR(VLOOKUP(E21,'DATA MASTER'!$B$1:$R$3858,5,0),"") -> 5.388 | J21: =IFERROR(VLOOKUP(E21,'DATA MASTER'!$B$1:$R$3858,17,0),"") -> 185700 | K21: =IFERROR(VLOOKUP(E21,'DATA MASTER'!$B$1:$R$3858,16,0),"") -> 165300 | L21: =IFERROR(IF(F21="MTAB",12.5%*J21,7.5%*J21),"") -> 13927.5 | M21: =IFERROR(IF(F21="MTAB",19.011%*K21,14.488%*K21),"") -> 23948.664 | N21: 0 | O21: 0 | R21: =IFERROR((((J21-L21)/1.11*(100-O21)%*G21)-(ROUNDDOWN(G21/Y21,0)*N21)),"") -> 619000 | S21: =IFERROR((K21-M21)/1.11*(100-O21)%*G21,"") -> 509374.18 | T21: =IFERROR(R21-S21,"") -> 109625.82 | U21: =IFERROR(I21*G21*700,"") -> 15086.4 | V21: =IFERROR(G21*I21/23000*1500000,"") -> 1405.5652 | W21: =IFERROR(2%*R21*1.11,"") -> 13741.8 | X21: =IFERROR(T21-U21-V21-W21-Z21-AC21-AB21-AA21-AD21,"") -> 79392.051 | Y21: 1 | Z21: 0 | AA21: =IFERROR(ROUNDDOWN(G21/Y21,0)*P21,"") -> 0 | AB21: =IFERROR(IF(OR(D21="SALES008",D21="SALES010"),IF(MOD(G21,H21)=0,10000*G21/H21,10000*(ROUNDUP(G21/H21,0))),0),"") -> 0 | AC21: 0 | AD21: 0 | AF21: ABEM005KSW | AG21: =SUMIF($E$8:$X$2162,AF21,$R$8:$R$2162)*1.11 -> 1318680 | AH21: =SUMIF($E$8:$X$1048576,AF21,$X$8:$X$1048576) -> 136742.63 | AI21: =AH21/AG21 -> 0.1036966
A22: 15 | B22: 46235 | C22: SO.AV.2026.08.00013 | D22: SALES006 | E22: AVEM005 | F22: =IFERROR(VLOOKUP(E22,'DATA MASTER'!$B$1:$R$3858,3,0),"") -> DIV 1 | G22: 4 | H22: =IFERROR(VLOOKUP(E22,'DATA MASTER'!$B$1:$R$3858,6,0),"") -> 4 | I22: =IFERROR(VLOOKUP(E22,'DATA MASTER'!$B$1:$R$3858,5,0),"") -> 5.388 | J22: =IFERROR(VLOOKUP(E22,'DATA MASTER'!$B$1:$R$3858,17,0),"") -> 185700 | K22: =IFERROR(VLOOKUP(E22,'DATA MASTER'!$B$1:$R$3858,16,0),"") -> 165300 | L22: =IFERROR(IF(F22="MTAB",12.5%*J22,7.5%*J22),"") -> 13927.5 | M22: =IFERROR(IF(F22="MTAB",19.011%*K22,14.488%*K22),"") -> 23948.664 | N22: 0 | O22: 0 | R22: =IFERROR((((J22-L22)/1.11*(100-O22)%*G22)-(ROUNDDOWN(G22/Y22,0)*N22)),"") -> 619000 | S22: =IFERROR((K22-M22)/1.11*(100-O22)%*G22,"") -> 509374.18 | T22: =IFERROR(R22-S22,"") -> 109625.82 | U22: =IFERROR(I22*G22*700,"") -> 15086.4 | V22: =IFERROR(G22*I22/23000*1500000,"") -> 1405.5652 | W22: =IFERROR(2%*R22*1.11,"") -> 13741.8 | X22: =IFERROR(T22-U22-V22-W22-Z22-AC22-AB22-AA22-AD22,"") -> 79392.051 | Y22: 1 | Z22: 0 | AA22: =IFERROR(ROUNDDOWN(G22/Y22,0)*P22,"") -> 0 | AB22: =IFERROR(IF(OR(D22="SALES008",D22="SALES010"),IF(MOD(G22,H22)=0,10000*G22/H22,10000*(ROUNDUP(G22/H22,0))),0),"") -> 0 | AC22: 0 | AD22: 0 | AF22: ABEM020 | AG22: =SUMIF($E$8:$X$2162,AF22,$R$8:$R$2162)*1.11 -> 2117880 | AH22: =SUMIF($E$8:$X$1048576,AF22,$X$8:$X$1048576) -> 269500.28 | AI22: =AH22/AG22 -> 0.12725002
A23: 16 | B23: 46235 | C23: SO.AV.2026.08.00013 | D23: SALES006 | E23: AVEM025 | F23: =IFERROR(VLOOKUP(E23,'DATA MASTER'!$B$1:$R$3858,3,0),"") -> DIV 1 | G23: 1 | H23: =IFERROR(VLOOKUP(E23,'DATA MASTER'!$B$1:$R$3858,6,0),"") -> 1 | I23: =IFERROR(VLOOKUP(E23,'DATA MASTER'!$B$1:$R$3858,5,0),"") -> 26.02 | J23: =IFERROR(VLOOKUP(E23,'DATA MASTER'!$B$1:$R$3858,17,0),"") -> 876000 | K23: =IFERROR(VLOOKUP(E23,'DATA MASTER'!$B$1:$R$3858,16,0),"") -> 777200 | L23: =IFERROR(IF(F23="MTAB",12.5%*J23,7.5%*J23),"") -> 65700 | M23: =IFERROR(IF(F23="MTAB",19.011%*K23,14.488%*K23),"") -> 112600.74 | N23: 0 | O23: 0 | R23: =IFERROR((((J23-L23)/1.11*(100-O23)%*G23)-(ROUNDDOWN(G23/Y23,0)*N23)),"") -> 730000 | S23: =IFERROR((K23-M23)/1.11*(100-O23)%*G23,"") -> 598738.08 | T23: =IFERROR(R23-S23,"") -> 131261.92 | U23: =IFERROR(I23*G23*700,"") -> 18214 | V23: =IFERROR(G23*I23/23000*1500000,"") -> 1696.9565 | W23: =IFERROR(2%*R23*1.11,"") -> 16206 | X23: =IFERROR(T23-U23-V23-W23-Z23-AC23-AB23-AA23-AD23,"") -> 95144.968 | Y23: 1 | Z23: 0 | AA23: =IFERROR(ROUNDDOWN(G23/Y23,0)*P23,"") -> 0 | AB23: =IFERROR(IF(OR(D23="SALES008",D23="SALES010"),IF(MOD(G23,H23)=0,10000*G23/H23,10000*(ROUNDUP(G23/H23,0))),0),"") -> 0 | AC23: 0 | AD23: 0 | AF23: ABEM020KP725 | AG23: =SUMIF($E$8:$X$2162,AF23,$R$8:$R$2162)*1.11 -> 635364 | AH23: =SUMIF($E$8:$X$1048576,AF23,$X$8:$X$1048576) -> 82978.502 | AI23: =AH23/AG23 -> 0.13059994
A24: 17 | B24: 46235 | C24: SO.AV.2026.08.00014 | D24: SALES001 | E24: AVGO025 | F24: =IFERROR(VLOOKUP(E24,'DATA MASTER'!$B$1:$R$3858,3,0),"") -> DIV 1 | G24: 2 | H24: =IFERROR(VLOOKUP(E24,'DATA MASTER'!$B$1:$R$3858,6,0),"") -> 1 | I24: =IFERROR(VLOOKUP(E24,'DATA MASTER'!$B$1:$R$3858,5,0),"") -> 26.01 | J24: =IFERROR(VLOOKUP(E24,'DATA MASTER'!$B$1:$R$3858,17,0),"") -> 1103500 | K24: =IFERROR(VLOOKUP(E24,'DATA MASTER'!$B$1:$R$3858,16,0),"") -> 991800 | L24: =IFERROR(IF(F24="MTAB",12.5%*J24,7.5%*J24),"") -> 82762.5 | M24: =IFERROR(IF(F24="MTAB",19.011%*K24,14.488%*K24),"") -> 143691.98 | N24: 0 | O24: 0 | Q24: =VLOOKUP(#REF!,#REF!,1,0) -> #REF! | R24: =IFERROR((((J24-L24)/1.11*(100-O24)%*G24)-(ROUNDDOWN(G24/Y24,0)*N24)),"") -> 1839166.7 | S24: =IFERROR((K24-M24)/1.11*(100-O24)%*G24,"") -> 1528122.6 | T24: =IFERROR(R24-S24,"") -> 311044.12 | U24: =IFERROR(I24*G24*700,"") -> 36414 | V24: =IFERROR(G24*I24/23000*1500000,"") -> 3392.6087 | W24: 0 | X24: =IFERROR(T24-U24-V24-W24-Z24-AC24-AB24-AA24-AD24,"") | Y24: 1 | Z24: =VLOOKUP(Q24,#REF!,4,0) -> #REF! | AA24: =IFERROR(ROUNDDOWN(G24/Y24,0)*P24,"") -> 0 | AB24: =IFERROR(IF(OR(D24="SALES008",D24="SALES010"),IF(MOD(G24,H24)=0,10000*G24/H24,10000*(ROUNDUP(G24/H24,0))),0),"") -> 0 | AC24: =Z24*R24*1.11 -> #REF! | AD24: 0 | AF24: ABEM020KPBA | AG24: =SUMIF($E$8:$X$2162,AF24,$R$8:$R$2162)*1.11 -> 631925 | AH24: =SUMIF($E$8:$X$1048576,AF24,$X$8:$X$1048576) -> 53395.201 | AI24: =AH24/AG24 -> 0.084496105
A25: 18 | B25: 46235 | C25: SO.AV.2026.08.00015 | D25: SALES002 | E25: NODR001 | F25: =IFERROR(VLOOKUP(E25,'DATA MASTER'!$B$1:$R$3858,3,0),"") -> DIV 2 | G25: 2 | H25: =IFERROR(VLOOKUP(E25,'DATA MASTER'!$B$1:$R$3858,6,0),"") -> 24 | I25: =IFERROR(VLOOKUP(E25,'DATA MASTER'!$B$1:$R$3858,5,0),"") -> 1.09 | J25: =IFERROR(VLOOKUP(E25,'DATA MASTER'!$B$1:$R$3858,17,0),"") -> 82200 | K25: =IFERROR(VLOOKUP(E25,'DATA MASTER'!$B$1:$R$3858,16,0),"") -> 74900 | L25: =IFERROR(IF(F25="MTAB",12.5%*J25,7.5%*J25),"") -> 6165 | M25: =IFERROR(IF(F25="MTAB",19.011%*K25,14.488%*K25),"") -> 10851.512 | N25: 0 | O25: 0 | R25: =IFERROR((((J25-L25)/1.11*(100-O25)%*G25)-(ROUNDDOWN(G25/Y25,0)*N25)),"") -> 137000 | S25: =IFERROR((K25-M25)/1.11*(100-O25)%*G25,"") -> 115402.68 | T25: =IFERROR(R25-S25,"") -> 21597.319 | U25: =IFERROR(I25*G25*700,"") -> 1526 | V25: =IFERROR(G25*I25/23000*1500000,"") -> 142.17391 | W25: =IFERROR(2%*R25*1.11,"") -> 3041.4 | X25: =IFERROR(T25-U25-V25-W25-Z25-AC25-AB25-AA25-AD25,"") -> 8554.4117 | Y25: 1 | Z25: 0 | AA25: =IFERROR(ROUNDDOWN(G25/Y25,0)*P25,"") -> 0 | AB25: =IFERROR(IF(OR(D25="SALES008",D25="SALES010"),IF(MOD(G25,H25)=0,10000*G25/H25,10000*(ROUNDUP(G25/H25,0))),0),"") -> 0 | AC25: 0 | AD25: 8333.3333 | AF25: ABEM020KPBC | AG25: =SUMIF($E$8:$X$2162,AF25,$R$8:$R$2162)*1.11 -> 587300 | AH25: =SUMIF($E$8:$X$1048576,AF25,$X$8:$X$1048576) -> 54858.939 | AI25: =AH25/AG25 -> 0.093408717
A26: 19 | B26: 46235 | C26: SO.AV.2026.08.00016 | D26: SALES002 | E26: ABEM020 | F26: =IFERROR(VLOOKUP(E26,'DATA MASTER'!$B$1:$R$3858,3,0),"") -> DIV 2 | G26: 1 | H26: =IFERROR(VLOOKUP(E26,'DATA MASTER'!$B$1:$R$3858,6,0),"") -> 1 | I26: =IFERROR(VLOOKUP(E26,'DATA MASTER'!$B$1:$R$3858,5,0),"") -> 19.01 | J26: =IFERROR(VLOOKUP(E26,'DATA MASTER'!$B$1:$R$3858,17,0),"") -> 381600 | K26: =IFERROR(VLOOKUP(E26,'DATA MASTER'!$B$1:$R$3858,16,0),"") -> 322800 | L26: =IFERROR(IF(F26="MTAB",12.5%*J26,7.5%*J26),"") -> 28620 | M26: =IFERROR(IF(F26="MTAB",19.011%*K26,14.488%*K26),"") -> 46767.264 | N26: 0 | O26: 0 | R26: =IFERROR((((J26-L26)/1.11*(100-O26)%*G26)-(ROUNDDOWN(G26/Y26,0)*N26)),"") -> 318000 | S26: =IFERROR((K26-M26)/1.11*(100-O26)%*G26,"") -> 248678.14 | T26: =IFERROR(R26-S26,"") -> 69321.859 | U26: =IFERROR(I26*G26*700,"") -> 13307 | V26: =IFERROR(G26*I26/23000*1500000,"") -> 1239.7826 | W26: =IFERROR(2%*R26*1.11,"") -> 7059.6 | X26: =IFERROR(T26-U26-V26-W26-Z26-AC26-AB26-AA26-AD26,"") -> 44590.477 | Y26: 1 | Z26: 0 | AA26: =IFERROR(ROUNDDOWN(G26/Y26,0)*P26,"") -> 0 | AB26: =IFERROR(IF(OR(D26="SALES008",D26="SALES010"),IF(MOD(G26,H26)=0,10000*G26/H26,10000*(ROUNDUP(G26/H26,0))),0),"") -> 0 | AC26: 0 | AD26: 3125 | AF26: ABEM020KPSW | AG26: =SUMIF($E$8:$X$2162,AF26,$R$8:$R$2162)*1.11 -> 2223774 | AH26: =SUMIF($E$8:$X$1048576,AF26,$X$8:$X$1048576) -> 283637.43 | AI26: =AH26/AG26 -> 0.12754778
A27: 20 | B27: 46235 | C27: SO.AV.2026.08.00017 | D27: SALES001 | E27: AGEM005 | F27: =IFERROR(VLOOKUP(E27,'DATA MASTER'!$B$1:$R$3858,3,0),"") -> DIV 2 | G27: 3 | H27: =IFERROR(VLOOKUP(E27,'DATA MASTER'!$B$1:$R$3858,6,0),"") -> 4 | I27: =IFERROR(VLOOKUP(E27,'DATA MASTER'!$B$1:$R$3858,5,0),"") -> 4.68 | J27: =IFERROR(VLOOKUP(E27,'DATA MASTER'!$B$1:$R$3858,17,0),"") -> 112100 | K27: =IFERROR(VLOOKUP(E27,'DATA MASTER'!$B$1:$R$3858,16,0),"") -> 96500 | L27: =IFERROR(IF(F27="MTAB",12.5%*J27,7.5%*J27),"") -> 8407.5 | M27: =IFERROR(IF(F27="MTAB",19.011%*K27,14.488%*K27),"") -> 13980.92 | N27: 0 | O27: 0 | R27: =IFERROR((((J27-L27)/1.11*(100-O27)%*G27)-(ROUNDDOWN(G27/Y27,0)*N27)),"") -> 280250 | S27: =IFERROR((K27-M27)/1.11*(100-O27)%*G27,"") -> 223024.54 | T27: =IFERROR(R27-S27,"") -> 57225.459 | U27: =IFERROR(I27*G27*700,"") -> 9828 | V27: =IFERROR(G27*I27/23000*1500000,"") -> 915.65217 | W27: =IFERROR(2%*R27*1.11,"") -> 6221.55 | X27: =IFERROR(T27-U27-V27-W27-Z27-AC27-AB27-AA27-AD27,"") -> 34377.904 | Y27: 1 | Z27: 0 | AA27: =IFERROR(ROUNDDOWN(G27/Y27,0)*P27,"") -> 0 | AB27: =IFERROR(IF(OR(D27="SALES008",D27="SALES010"),IF(MOD(G27,H27)=0,10000*G27/H27,10000*(ROUNDUP(G27/H27,0))),0),"") -> 0 | AC27: 0 | AD27: 5882.3529 | AF27: ACSY001 | AG27: =SUMIF($E$8:$X$2162,AF27,$R$8:$R$2162)*1.11 -> 1.2340148e+08 | AH27: =SUMIF($E$8:$X$1048576,AF27,$X$8:$X$1048576) -> 9929827.9 | AI27: =AH27/AG27 -> 0.08046766
A28: 21 | B28: 46235 | C28: SO.AV.2026.08.00017 | D28: SALES001 | E28: YOSY001 | F28: =IFERROR(VLOOKUP(E28,'DATA MASTER'!$B$1:$R$3858,3,0),"") -> DIV 2 | G28: 12 | H28: =IFERROR(VLOOKUP(E28,'DATA MASTER'!$B$1:$R$3858,6,0),"") -> 24 | I28: =IFERROR(VLOOKUP(E28,'DATA MASTER'!$B$1:$R$3858,5,0),"") -> 0.85 | J28: =IFERROR(VLOOKUP(E28,'DATA MASTER'!$B$1:$R$3858,17,0),"") -> 74700 | K28: =IFERROR(VLOOKUP(E28,'DATA MASTER'!$B$1:$R$3858,16,0),"") -> 67900 | L28: =IFERROR(IF(F28="MTAB",12.5%*J28,7.5%*J28),"") -> 5602.5 | M28: =IFERROR(IF(F28="MTAB",19.011%*K28,14.488%*K28),"") -> 9837.352 | N28: 0 | O28: 0 | R28: =IFERROR((((J28-L28)/1.11*(100-O28)%*G28)-(ROUNDDOWN(G28/Y28,0)*N28)),"") -> 747000 | S28: =IFERROR((K28-M28)/1.11*(100-O28)%*G28,"") -> 627704.3 | T28: =IFERROR(R28-S28,"") -> 119295.7 | U28: =IFERROR(I28*G28*700,"") -> 7140 | V28: =IFERROR(G28*I28/23000*1500000,"") -> 665.21739 | W28: =IFERROR(2%*R28*1.11,"") -> 16583.4 | X28: =IFERROR(T28-U28-V28-W28-Z28-AC28-AB28-AA28-AD28,"") -> 89024.727 | Y28: 1 | Z28: 0 | AA28: =IFERROR(ROUNDDOWN(G28/Y28,0)*P28,"") -> 0 | AB28: =IFERROR(IF(OR(D28="SALES008",D28="SALES010"),IF(MOD(G28,H28)=0,10000*G28/H28,10000*(ROUNDUP(G28/H28,0))),0),"") -> 0 | AC28: 0 | AD28: 5882.3529 | AF28: ACSY002 | AG28: =SUMIF($E$8:$X$2162,AF28,$R$8:$R$2162)*1.11 -> 587661.75 | AH28: =SUMIF($E$8:$X$1048576,AF28,$X$8:$X$1048576) -> 62140.134 | AI28: =AH28/AG28 -> 0.10574133
A29: 22 | B29: 46235 | C29: SO.AV.2026.08.00018 | D29: SALES006 | E29: NODR020 | F29: =IFERROR(VLOOKUP(E29,'DATA MASTER'!$B$1:$R$3858,3,0),"") -> DIV 2 | G29: 2 | H29: =IFERROR(VLOOKUP(E29,'DATA MASTER'!$B$1:$R$3858,6,0),"") -> 1 | I29: =IFERROR(VLOOKUP(E29,'DATA MASTER'!$B$1:$R$3858,5,0),"") -> 21.11 | J29: =IFERROR(VLOOKUP(E29,'DATA MASTER'!$B$1:$R$3858,17,0),"") -> 1428200 | K29: =IFERROR(VLOOKUP(E29,'DATA MASTER'!$B$1:$R$3858,16,0),"") -> 1291700 | L29: =IFERROR(IF(F29="MTAB",12.5%*J29,7.5%*J29),"") -> 107115 | M29: =IFERROR(IF(F29="MTAB",19.011%*K29,14.488%*K29),"") -> 187141.5 | N29: 0 | O29: 0 | R29: =IFERROR((((J29-L29)/1.11*(100-O29)%*G29)-(ROUNDDOWN(G29/Y29,0)*N29)),"") -> 2380333.3 | S29: =IFERROR((K29-M29)/1.11*(100-O29)%*G29,"") -> 1990195.5 | T29: =IFERROR(R29-S29,"") -> 390137.83 | U29: =IFERROR(I29*G29*700,"") -> 29554 | V29: =IFERROR(G29*I29/23000*1500000,"") -> 2753.4783 | W29: =IFERROR(2%*R29*1.11,"") -> 52843.4 | X29: =IFERROR(T29-U29-V29-W29-Z29-AC29-AB29-AA29-AD29,"") -> 294986.95 | Y29: 1 | Z29: 0 | AA29: =IFERROR(ROUNDDOWN(G29/Y29,0)*P29,"") -> 0 | AB29: =IFERROR(IF(OR(D29="SALES008",D29="SALES010"),IF(MOD(G29,H29)=0,10000*G29/H29,10000*(ROUNDUP(G29/H29,0))),0),"") -> 0 | AC29: 0 | AD29: 10000 | AF29: ACSY004 | AG29: =SUMIF($E$8:$X$2162,AF29,$R$8:$R$2162)*1.11 -> 2917579.5 | AH29: =SUMIF($E$8:$X$1048576,AF29,$X$8:$X$1048576) -> 184904.83 | AI29: =AH29/AG29 -> 0.063376108
A30: 23 | B30: 46235 | C30: SO.AV.2026.08.00019 | D30: SALES002 | E30: AVSY001 | F30: =IFERROR(VLOOKUP(E30,'DATA MASTER'!$B$1:$R$3858,3,0),"") -> DIV 1 | G30: 2 | H30: =IFERROR(VLOOKUP(E30,'DATA MASTER'!$B$1:$R$3858,6,0),"") -> 24 | I30: =IFERROR(VLOOKUP(E30,'DATA MASTER'!$B$1:$R$3858,5,0),"") -> 1.23 | J30: =IFERROR(VLOOKUP(E30,'DATA MASTER'!$B$1:$R$3858,17,0),"") -> 99800 | K30: =IFERROR(VLOOKUP(E30,'DATA MASTER'!$B$1:$R$3858,16,0),"") -> 92100 | L30: =IFERROR(IF(F30="MTAB",12.5%*J30,7.5%*J30),"") -> 7485 | M30: =IFERROR(IF(F30="MTAB",19.011%*K30,14.488%*K30),"") -> 13343.448 | N30: 0 | O30: 0 | R30: =IFERROR((((J30-L30)/1.11*(100-O30)%*G30)-(ROUNDDOWN(G30/Y30,0)*N30)),"") -> 166333.33 | S30: =IFERROR((K30-M30)/1.11*(100-O30)%*G30,"") -> 141903.7 | T30: =IFERROR(R30-S30,"") -> 24429.636 | U30: =IFERROR(I30*G30*700,"") -> 1722 | V30: =IFERROR(G30*I30/23000*1500000,"") -> 160.43478 | W30: =IFERROR(2%*R30*1.11,"") -> 3692.6 | X30: =IFERROR(T30-U30-V30-W30-Z30-AC30-AB30-AA30-AD30,"") -> 13085.37 | Y30: 1 | Z30: 0 | AA30: =IFERROR(ROUNDDOWN(G30/Y30,0)*P30,"") -> 0 | AB30: =IFERROR(IF(OR(D30="SALES008",D30="SALES010"),IF(MOD(G30,H30)=0,10000*G30/H30,10000*(ROUNDUP(G30/H30,0))),0),"") -> 0 | AC30: 0 | AD30: 5769.2308 | AF30: ACSY200 | AG30: =SUMIF($E$8:$X$2162,AF30,$R$8:$R$2162)*1.11 -> 4647181.5 | AH30: =SUMIF($E$8:$X$1048576,AF30,$X$8:$X$1048576) -> 364106.16 | AI30: =AH30/AG30 -> 0.07834989
A31: 24 | B31: 46235 | C31: SO.AV.2026.08.00020 | D31: SALES003 | E31: AVEM025 | F31: =IFERROR(VLOOKUP(E31,'DATA MASTER'!$B$1:$R$3858,3,0),"") -> DIV 1 | G31: 1 | H31: =IFERROR(VLOOKUP(E31,'DATA MASTER'!$B$1:$R$3858,6,0),"") -> 1 | I31: =IFERROR(VLOOKUP(E31,'DATA MASTER'!$B$1:$R$3858,5,0),"") -> 26.02 | J31: =IFERROR(VLOOKUP(E31,'DATA MASTER'!$B$1:$R$3858,17,0),"") -> 876000 | K31: =IFERROR(VLOOKUP(E31,'DATA MASTER'!$B$1:$R$3858,16,0),"") -> 777200 | L31: =IFERROR(IF(F31="MTAB",12.5%*J31,7.5%*J31),"") -> 65700 | M31: =IFERROR(IF(F31="MTAB",19.011%*K31,14.488%*K31),"") -> 112600.74 | N31: 0 | O31: 0 | R31: =IFERROR((((J31-L31)/1.11*(100-O31)%*G31)-(ROUNDDOWN(G31/Y31,0)*N31)),"") -> 730000 | S31: =IFERROR((K31-M31)/1.11*(100-O31)%*G31,"") -> 598738.08 | T31: =IFERROR(R31-S31,"") -> 131261.92 | U31: =IFERROR(I31*G31*700,"") -> 18214 | V31: =IFERROR(G31*I31/23000*1500000,"") -> 1696.9565 | W31: =IFERROR(2%*R31*1.11,"") -> 16206 | X31: =IFERROR(T31-U31-V31-W31-Z31-AC31-AB31-AA31-AD31,"") -> 87452.66 | Y31: =IF(E31="avem005",4,IF(E31="avem025",1,1)) -> 1 | Z31: 0 | AA31: =IFERROR(ROUNDDOWN(G31/Y31,0)*P31,"") -> 0 | AB31: =IFERROR(IF(OR(D31="SALES008",D31="SALES010"),IF(MOD(G31,H31)=0,10000*G31/H31,10000*(ROUNDUP(G31/H31,0))),0),"") -> 0 | AC31: 0 | AD31: 7692.3077 | AF31: ACZI001 | AG31: =SUMIF($E$8:$X$2162,AF31,$R$8:$R$2162)*1.11 -> 1367520 | AH31: =SUMIF($E$8:$X$1048576,AF31,$X$8:$X$1048576) -> 126393.82 | AI31: =AH31/AG31 -> 0.092425574
A32: 25 | B32: 46235 | C32: SO.AV.2026.08.00021 | D32: SALES001 | E32: NOBI001 | F32: =IFERROR(VLOOKUP(E32,'DATA MASTER'!$B$1:$R$3858,3,0),"") -> DIV 2 | G32: 6 | H32: =IFERROR(VLOOKUP(E32,'DATA MASTER'!$B$1:$R$3858,6,0),"") -> 24 | I32: =IFERROR(VLOOKUP(E32,'DATA MASTER'!$B$1:$R$3858,5,0),"") -> 1.084 | J32: =IFERROR(VLOOKUP(E32,'DATA MASTER'!$B$1:$R$3858,17,0),"") -> 54000 | K32: =IFERROR(VLOOKUP(E32,'DATA MASTER'!$B$1:$R$3858,16,0),"") -> 48900 | L32: =IFERROR(IF(F32="MTAB",12.5%*J32,7.5%*J32),"") -> 4050 | M32: =IFERROR(IF(F32="MTAB",19.011%*K32,14.488%*K32),"") -> 7084.632 | N32: 0 | O32: 0 | Q32: =VLOOKUP(#REF!,#REF!,1,0) -> #REF! | R32: =IFERROR((((J32-L32)/1.11*(100-O32)%*G32)-(ROUNDDOWN(G32/Y32,0)*N32)),"") -> 270000 | S32: =IFERROR((K32-M32)/1.11*(100-O32)%*G32,"") -> 226029.02 | T32: =IFERROR(R32-S32,"") -> 43970.984 | U32: =IFERROR(I32*G32*700,"") -> 4552.8 | V32: =IFERROR(G32*I32/23000*1500000,"") -> 424.17391 | W32: =IFERROR(2%*R32*1.11,"") -> 5994 | X32: =IFERROR(T32-U32-V32-W32-Z32-AC32-AB32-AA32-AD32,"") | Y32: 1 | Z32: =VLOOKUP(Q32,#REF!,4,0) -> #REF! | AA32: =IFERROR(ROUNDDOWN(G32/Y32,0)*P32,"") -> 0 | AB32: =IFERROR(IF(OR(D32="SALES008",D32="SALES010"),IF(MOD(G32,H32)=0,10000*G32/H32,10000*(ROUNDUP(G32/H32,0))),0),"") -> 0 | AC32: =Z32*R32*1.11 -> #REF! | AD32: 0 | AF32: ADFO005 | AG32: =SUMIF($E$8:$X$2162,AF32,$R$8:$R$2162)*1.11 -> 1666850 | AH32: =SUMIF($E$8:$X$1048576,AF32,$X$8:$X$1048576) -> 199043.65 | AI32: =AH32/AG32 -> 0.11941305
A33: 26 | B33: 46235 | C33: SO.AV.2026.08.00022 | D33: SALES012 | E33: AVSY001 | F33: =IFERROR(VLOOKUP(E33,'DATA MASTER'!$B$1:$R$3858,3,0),"") -> DIV 1 | G33: 6 | H33: =IFERROR(VLOOKUP(E33,'DATA MASTER'!$B$1:$R$3858,6,0),"") -> 24 | I33: =IFERROR(VLOOKUP(E33,'DATA MASTER'!$B$1:$R$3858,5,0),"") -> 1.23 | J33: =IFERROR(VLOOKUP(E33,'DATA MASTER'!$B$1:$R$3858,17,0),"") -> 99800 | K33: =IFERROR(VLOOKUP(E33,'DATA MASTER'!$B$1:$R$3858,16,0),"") -> 92100 | L33: =IFERROR(IF(F33="MTAB",12.5%*J33,7.5%*J33),"") -> 7485 | M33: =IFERROR(IF(F33="MTAB",19.011%*K33,14.488%*K33),"") -> 13343.448 | N33: 0 | O33: 0 | R33: =IFERROR((((J33-L33)/1.11*(100-O33)%*G33)-(ROUNDDOWN(G33/Y33,0)*N33)),"") -> 499000 | S33: =IFERROR((K33-M33)/1.11*(100-O33)%*G33,"") -> 425711.09 | T33: =IFERROR(R33-S33,"") -> 73288.908 | U33: =IFERROR(I33*G33*700,"") -> 5166 | V33: =IFERROR(G33*I33/23000*1500000,"") -> 481.30435 | W33: =IFERROR(2%*R33*1.11,"") -> 11077.8 | X33: =IFERROR(T33-U33-V33-W33-Z33-AC33-AB33-AA33-AD33,"") -> 49420.947 | Y33: 1 | Z33: 0 | AA33: =IFERROR(ROUNDDOWN(G33/Y33,0)*P33,"") -> 0 | AB33: =IFERROR(IF(OR(D33="SALES008",D33="SALES010"),IF(MOD(G33,H33)=0,10000*G33/H33,10000*(ROUNDUP(G33/H33,0))),0),"") -> 0 | AC33: 0 | AD33: 7142.8571 | AF33: AGEM001 | AG33: =SUMIF($E$8:$X$2162,AF33,$R$8:$R$2162)*1.11 -> 2109555 | AH33: =SUMIF($E$8:$X$1048576,AF33,$X$8:$X$1048576) -> 130097.7 | AI33: =AH33/AG33 -> 0.061670685
A34: 27 | B34: 46235 | C34: SO.AV.2026.08.00023 | D34: SALES010 | E34: AGEM005 | F34: =IFERROR(VLOOKUP(E34,'DATA MASTER'!$B$1:$R$3858,3,0),"") -> DIV 2 | G34: 8 | H34: =IFERROR(VLOOKUP(E34,'DATA MASTER'!$B$1:$R$3858,6,0),"") -> 4 | I34: =IFERROR(VLOOKUP(E34,'DATA MASTER'!$B$1:$R$3858,5,0),"") -> 4.68 | J34: =IFERROR(VLOOKUP(E34,'DATA MASTER'!$B$1:$R$3858,17,0),"") -> 112100 | K34: =IFERROR(VLOOKUP(E34,'DATA MASTER'!$B$1:$R$3858,16,0),"") -> 96500 | L34: =IFERROR(IF(F34="MTAB",12.5%*J34,7.5%*J34),"") -> 8407.5 | M34: =IFERROR(IF(F34="MTAB",19.011%*K34,14.488%*K34),"") -> 13980.92 | N34: 0 | O34: 0 | R34: =IFERROR((((J34-L34)/1.11*(100-O34)%*G34)-(ROUNDDOWN(G34/Y34,0)*N34)),"") -> 747333.33 | S34: =IFERROR((K34-M34)/1.11*(100-O34)%*G34,"") -> 594732.11 | T34: =IFERROR(R34-S34,"") -> 152601.23 | U34: =IFERROR(I34*G34*700,"") -> 26208 | V34: =IFERROR(G34*I34/23000*1500000,"") -> 2441.7391 | W34: =IFERROR(2%*R34*1.11,"") -> 16590.8 | X34: =IFERROR(T34-U34-V34-W34-Z34-AC34-AB34-AA34-AD34,"") -> 87360.686 | Y34: 1 | Z34: 0 | AA34: =IFERROR(ROUNDDOWN(G34/Y34,0)*P34,"") -> 0 | AB34: =IFERROR(IF(OR(D34="SALES008",D34="SALES010"),IF(MOD(G34,H34)=0,10000*G34/H34,10000*(ROUNDUP(G34/H34,0))),0),"") -> 20000 | AC34: 0 | AD34: 0 | AF34: AGEM001KBA | AG34: =SUMIF($E$8:$X$2162,AF34,$R$8:$R$2162)*1.11 -> 126700 | AH34: =SUMIF($E$8:$X$1048576,AF34,$X$8:$X$1048576) -> 8400.4407 | AI34: =AH34/AG34 -> 0.066301821
A35: 28 | B35: 46235 | C35: SO.AV.2026.08.00024 | D35: SALES010 | E35: BOVE001KSW | F35: =IFERROR(VLOOKUP(E35,'DATA MASTER'!$B$1:$R$3858,3,0),"") -> DIV 1 | G35: 24 | H35: =IFERROR(VLOOKUP(E35,'DATA MASTER'!$B$1:$R$3858,6,0),"") -> 24 | I35: =IFERROR(VLOOKUP(E35,'DATA MASTER'!$B$1:$R$3858,5,0),"") -> 1.126 | J35: =IFERROR(VLOOKUP(E35,'DATA MASTER'!$B$1:$R$3858,17,0),"") -> 105400 | K35: =IFERROR(VLOOKUP(E35,'DATA MASTER'!$B$1:$R$3858,16,0),"") -> 96600 | L35: =IFERROR(IF(F35="MTAB",12.5%*J35,7.5%*J35),"") -> 7905 | M35: =IFERROR(IF(F35="MTAB",19.011%*K35,14.488%*K35),"") -> 13995.408 | N35: 0 | O35: 0 | R35: =IFERROR((((J35-L35)/1.11*(100-O35)%*G35)-(ROUNDDOWN(G35/Y35,0)*N35)),"") -> 2108000 | S35: =IFERROR((K35-M35)/1.11*(100-O35)%*G35,"") -> 1786045.2 | T35: =IFERROR(R35-S35,"") -> 321954.77 | U35: =IFERROR(I35*G35*700,"") -> 18916.8 | V35: =IFERROR(G35*I35/23000*1500000,"") -> 1762.4348 | W35: =IFERROR(2%*R35*1.11,"") -> 46797.6 | X35: =IFERROR(T35-U35-V35-W35-Z35-AC35-AB35-AA35-AD35,"") -> 230192.22 | Y35: 1 | Z35: 0 | AA35: =IFERROR(ROUNDDOWN(G35/Y35,0)*P35,"") -> 0 | AB35: =IFERROR(IF(OR(D35="SALES008",D35="SALES010"),IF(MOD(G35,H35)=0,10000*G35/H35,10000*(ROUNDUP(G35/H35,0))),0),"") -> 10000 | AC35: 0 | AD35: 14285.714 | AF35: AGEM001KBB | AG35: =SUMIF($E$8:$X$2162,AF35,$R$8:$R$2162)*1.11 -> 63350 | AH35: =SUMIF($E$8:$X$1048576,AF35,$X$8:$X$1048576) -> 4261.4378 | AI35: =AH35/AG35 -> 0.067268157
A36: 29 | B36: 46235 | C36: SO.AV.2026.08.00025 | D36: SALES003 | E36: ACSY001 | F36: =IFERROR(VLOOKUP(E36,'DATA MASTER'!$B$1:$R$3858,3,0),"") -> DIV 2 | G36: 4 | H36: =IFERROR(VLOOKUP(E36,'DATA MASTER'!$B$1:$R$3858,6,0),"") -> 24 | I36: =IFERROR(VLOOKUP(E36,'DATA MASTER'!$B$1:$R$3858,5,0),"") -> 0.902 | J36: =IFERROR(VLOOKUP(E36,'DATA MASTER'!$B$1:$R$3858,17,0),"") -> 81000 | K36: =IFERROR(VLOOKUP(E36,'DATA MASTER'!$B$1:$R$3858,16,0),"") -> 74300 | L36: =IFERROR(IF(F36="MTAB",12.5%*J36,7.5%*J36),"") -> 6075 | M36: =IFERROR(IF(F36="MTAB",19.011%*K36,14.488%*K36),"") -> 10764.584 | N36: 0 | O36: 10 | R36: =IFERROR((((J36-L36)/1.11*(100-O36)%*G36)-(ROUNDDOWN(G36/Y36,0)*N36)),"") -> 243000 | S36: =IFERROR((K36-M36)/1.11*(100-O36)%*G36,"") -> 206060.81 | T36: =IFERROR(R36-S36,"") -> 36939.191 | U36: =IFERROR(I36*G36*700,"") -> 2525.6 | V36: =IFERROR(G36*I36/23000*1500000,"") -> 235.30435 | W36: =IFERROR(2%*R36*1.11,"") -> 5394.6 | X36: =IFERROR(T36-U36-V36-W36-Z36-AC36-AB36-AA36-AD36,"") -> 28783.687 | Y36: 1 | Z36: 0 | AA36: =IFERROR(ROUNDDOWN(G36/Y36,0)*P36,"") -> 0 | AB36: =IFERROR(IF(OR(D36="SALES008",D36="SALES010"),IF(MOD(G36,H36)=0,10000*G36/H36,10000*(ROUNDUP(G36/H36,0))),0),"") -> 0 | AC36: 0 | AD36: 0 | AF36: AGEM001KBC | AG36: =SUMIF($E$8:$X$2162,AF36,$R$8:$R$2162)*1.11 -> 126700 | AH36: =SUMIF($E$8:$X$1048576,AF36,$X$8:$X$1048576) -> 8645.3103 | AI36: =AH36/AG36 -> 0.068234493
A37: 30 | B37: 46235 | C37: SO.AV.2026.08.00026 | D37: SALES019 | E37: AGEM020 | F37: =IFERROR(VLOOKUP(E37,'DATA MASTER'!$B$1:$R$3858,3,0),"") -> DIV 2 | G37: 7 | H37: =IFERROR(VLOOKUP(E37,'DATA MASTER'!$B$1:$R$3858,6,0),"") -> 1 | I37: =IFERROR(VLOOKUP(E37,'DATA MASTER'!$B$1:$R$3858,5,0),"") -> 18.84 | J37: =IFERROR(VLOOKUP(E37,'DATA MASTER'!$B$1:$R$3858,17,0),"") -> 432400 | K37: =IFERROR(VLOOKUP(E37,'DATA MASTER'!$B$1:$R$3858,16,0),"") -> 376500 | L37: =IFERROR(IF(F37="MTAB",12.5%*J37,7.5%*J37),"") -> 32430 | M37: =IFERROR(IF(F37="MTAB",19.011%*K37,14.488%*K37),"") -> 54547.32 | N37: 0 | O37: 0 | R37: =IFERROR((((J37-L37)/1.11*(100-O37)%*G37)-(ROUNDDOWN(G37/Y37,0)*N37)),"") -> 2522333.3 | S37: =IFERROR((K37-M37)/1.11*(100-O37)%*G37,"") -> 2030332.2 | T37: =IFERROR(R37-S37,"") -> 492001.12 | U37: =IFERROR(I37*G37*700,"") -> 92316 | V37: =IFERROR(G37*I37/23000*1500000,"") -> 8600.8696 | W37: =IFERROR(2%*R37*1.11,"") -> 55995.8 | X37: =IFERROR(T37-U37-V37-W37-Z37-AC37-AB37-AA37-AD37,"") -> 315088.45 | Y37: =IF(E37="arem005",20,IF(E37="arem020",5,1)) -> 1 | Z37: 0 | AA37: =IFERROR(ROUNDDOWN(G37/Y37,0)*P37,"") -> 0 | AB37: =IFERROR(IF(OR(D37="SALES008",D37="SALES010"),IF(MOD(G37,H37)=0,10000*G37/H37,10000*(ROUNDUP(G37/H37,0))),0),"") -> 0 | AC37: 0 | AD37: 20000 | AF37: AGEM005 | AG37: =SUMIF($E$8:$X$2162,AF37,$R$8:$R$2162)*1.11 -> 42306540 | AH37: =SUMIF($E$8:$X$1048576,AF37,$X$8:$X$1048576) -> 4393903.1 | AI37: =AH37/AG37 -> 0.10385872
A38: 31 | B38: 46235 | C38: SO.AV.2026.08.00027 | D38: SALES004 | E38: AVSY001 | F38: =IFERROR(VLOOKUP(E38,'DATA MASTER'!$B$1:$R$3858,3,0),"") -> DIV 1 | G38: 6 | H38: =IFERROR(VLOOKUP(E38,'DATA MASTER'!$B$1:$R$3858,6,0),"") -> 24 | I38: =IFERROR(VLOOKUP(E38,'DATA MASTER'!$B$1:$R$3858,5,0),"") -> 1.23 | J38: =IFERROR(VLOOKUP(E38,'DATA MASTER'!$B$1:$R$3858,17,0),"") -> 99800 | K38: =IFERROR(VLOOKUP(E38,'DATA MASTER'!$B$1:$R$3858,16,0),"") -> 92100 | L38: =IFERROR(IF(F38="MTAB",12.5%*J38,7.5%*J38),"") -> 7485 | M38: =IFERROR(IF(F38="MTAB",19.011%*K38,14.488%*K38),"") -> 13343.448 | N38: 0 | O38: 0 | R38: =IFERROR((((J38-L38)/1.11*(100-O38)%*G38)-(ROUNDDOWN(G38/Y38,0)*N38)),"") -> 499000 | S38: =IFERROR((K38-M38)/1.11*(100-O38)%*G38,"") -> 425711.09 | T38: =IFERROR(R38-S38,"") -> 73288.908 | U38: =IFERROR(I38*G38*700,"") -> 5166 | V38: =IFERROR(G38*I38/23000*1500000,"") -> 481.30435 | W38: =IFERROR(2%*R38*1.11,"") -> 11077.8 | X38: =IFERROR(T38-U38-V38-W38-Z38-AC38-AB38-AA38-AD38,"") -> 56563.804 | Y38: 1 | Z38: 0 | AA38: =IFERROR(ROUNDDOWN(G38/Y38,0)*P38,"") -> 0 | AB38: =IFERROR(IF(OR(D38="SALES008",D38="SALES010"),IF(MOD(G38,H38)=0,10000*G38/H38,10000*(ROUNDUP(G38/H38,0))),0),"") -> 0 | AC38: 0 | AD38: 0 | AF38: AGEM005KBA | AG38: =SUMIF($E$8:$X$2162,AF38,$R$8:$R$2162)*1.11 -> 934500 | AH38: =SUMIF($E$8:$X$1048576,AF38,$X$8:$X$1048576) -> 60171.159 | AI38: =AH38/AG38 -> 0.064388614
A39: 32 | B39: 46235 | C39: SO.AV.2026.08.00028 | D39: SALES012 | E39: AVSY001 | F39: =IFERROR(VLOOKUP(E39,'DATA MASTER'!$B$1:$R$3858,3,0),"") -> DIV 1 | G39: 8 | H39: =IFERROR(VLOOKUP(E39,'DATA MASTER'!$B$1:$R$3858,6,0),"") -> 24 | I39: =IFERROR(VLOOKUP(E39,'DATA MASTER'!$B$1:$R$3858,5,0),"") -> 1.23 | J39: =IFERROR(VLOOKUP(E39,'DATA MASTER'!$B$1:$R$3858,17,0),"") -> 99800 | K39: =IFERROR(VLOOKUP(E39,'DATA MASTER'!$B$1:$R$3858,16,0),"") -> 92100 | L39: =IFERROR(IF(F39="MTAB",12.5%*J39,7.5%*J39),"") -> 7485 | M39: =IFERROR(IF(F39="MTAB",19.011%*K39,14.488%*K39),"") -> 13343.448 | N39: 0 | O39: 0 | R39: =IFERROR((((J39-L39)/1.11*(100-O39)%*G39)-(ROUNDDOWN(G39/Y39,0)*N39)),"") -> 665333.33 | S39: =IFERROR((K39-M39)/1.11*(100-O39)%*G39,"") -> 567614.79 | T39: =IFERROR(R39-S39,"") -> 97718.544 | U39: =IFERROR(I39*G39*700,"") -> 6888 | V39: =IFERROR(G39*I39/23000*1500000,"") -> 641.73913 | W39: =IFERROR(2%*R39*1.11,"") -> 14770.4 | X39: =IFERROR(T39-U39-V39-W39-Z39-AC39-AB39-AA39-AD39,"") -> 67085.072 | Y39: 1 | Z39: 0 | AA39: =IFERROR(ROUNDDOWN(G39/Y39,0)*P39,"") -> 0 | AB39: =IFERROR(IF(OR(D39="SALES008",D39="SALES010"),IF(MOD(G39,H39)=0,10000*G39/H39,10000*(ROUNDUP(G39/H39,0))),0),"") -> 0 | AC39: 0 | AD39: 8333.3333 | AF39: AGEM005KBB | AG39: =SUMIF($E$8:$X$2162,AF39,$R$8:$R$2162)*1.11 -> 1080450 | AH39: =SUMIF($E$8:$X$1048576,AF39,$X$8:$X$1048576) -> 69695.88 | AI39: =AH39/AG39 -> 0.064506344
A40: 33 | B40: 46235 | C40: SO.AV.2026.08.00029 | D40: SALES002 | E40: AVSY001 | F40: =IFERROR(VLOOKUP(E40,'DATA MASTER'!$B$1:$R$3858,3,0),"") -> DIV 1 | G40: 24 | H40: =IFERROR(VLOOKUP(E40,'DATA MASTER'!$B$1:$R$3858,6,0),"") -> 24 | I40: =IFERROR(VLOOKUP(E40,'DATA MASTER'!$B$1:$R$3858,5,0),"") -> 1.23 | J40: =IFERROR(VLOOKUP(E40,'DATA MASTER'!$B$1:$R$3858,17,0),"") -> 99800 | K40: =IFERROR(VLOOKUP(E40,'DATA MASTER'!$B$1:$R$3858,16,0),"") -> 92100 | L40: =IFERROR(IF(F40="MTAB",12.5%*J40,7.5%*J40),"") -> 7485 | M40: =IFERROR(IF(F40="MTAB",19.011%*K40,14.488%*K40),"") -> 13343.448 | N40: 0 | O40: 0 | P40: 60000 | Q40: 148 | R40: =IFERROR((((J40-L40)/1.11*(100-O40)%*G40)-(ROUNDDOWN(G40/Y40,0)*N40)),"") -> 1996000 | S40: =IFERROR((K40-M40)/1.11*(100-O40)%*G40,"") -> 1702844.4 | T40: =IFERROR(R40-S40,"") -> 293155.63 | U40: =IFERROR(I40*G40*700,"") -> 20664 | V40: =IFERROR(G40*I40/23000*1500000,"") -> 1925.2174 | W40: =IFERROR(2%*R40*1.11,"") -> 44311.2 | X40: =IFERROR(T40-U40-V40-W40-Z40-AC40-AB40-AA40-AD40,"") -> 152618.85 | Y40: 24 | Z40: 0 | AA40: =IFERROR(ROUNDDOWN(G40/Y40,0)*P40,"") -> 60000 | AB40: =IFERROR(IF(OR(D40="SALES008",D40="SALES010"),IF(MOD(G40,H40)=0,10000*G40/H40,10000*(ROUNDUP(G40/H40,0))),0),"") -> 0 | AC40: 0 | AD40: 13636.364 | AF40: AGEM005KBC | AG40: =SUMIF($E$8:$X$2162,AF40,$R$8:$R$2162)*1.11 -> 606987.5 | AH40: =SUMIF($E$8:$X$1048576,AF40,$X$8:$X$1048576) -> 49838.914 | AI40: =AH40/AG40 -> 0.082108633
A41: 34 | B41: 46235 | C41: SO.AV.2026.08.00030 | D41: SALES002 | E41: AVEM025 | F41: =IFERROR(VLOOKUP(E41,'DATA MASTER'!$B$1:$R$3858,3,0),"") -> DIV 1 | G41: 1 | H41: =IFERROR(VLOOKUP(E41,'DATA MASTER'!$B$1:$R$3858,6,0),"") -> 1 | I41: =IFERROR(VLOOKUP(E41,'DATA MASTER'!$B$1:$R$3858,5,0),"") -> 26.02 | J41: =IFERROR(VLOOKUP(E41,'DATA MASTER'!$B$1:$R$3858,17,0),"") -> 876000 | K41: =IFERROR(VLOOKUP(E41,'DATA MASTER'!$B$1:$R$3858,16,0),"") -> 777200 | L41: =IFERROR(IF(F41="MTAB",12.5%*J41,7.5%*J41),"") -> 65700 | M41: =IFERROR(IF(F41="MTAB",19.011%*K41,14.488%*K41),"") -> 112600.74 | N41: 0 | O41: 0 | R41: =IFERROR((((J41-L41)/1.11*(100-O41)%*G41)-(ROUNDDOWN(G41/Y41,0)*N41)),"") -> 730000 | S41: =IFERROR((K41-M41)/1.11*(100-O41)%*G41,"") -> 598738.08 | T41: =IFERROR(R41-S41,"") -> 131261.92 | U41: =IFERROR(I41*G41*700,"") -> 18214 | V41: =IFERROR(G41*I41/23000*1500000,"") -> 1696.9565 | W41: =IFERROR(2%*R41*1.11,"") -> 16206 | X41: =IFERROR(T41-U41-V41-W41-Z41-AC41-AB41-AA41-AD41,"") -> 95144.968 | Y41: 1 | Z41: 0 | AA41: =IFERROR(ROUNDDOWN(G41/Y41,0)*P41,"") -> 0 | AB41: =IFERROR(IF(OR(D41="SALES008",D41="SALES010"),IF(MOD(G41,H41)=0,10000*G41/H41,10000*(ROUNDUP(G41/H41,0))),0),"") -> 0 | AC41: 0 | AD41: 0 | AF41: AGEM020 | AG41: =SUMIF($E$8:$X$2162,AF41,$R$8:$R$2162)*1.11 -> 37197210 | AH41: =SUMIF($E$8:$X$1048576,AF41,$X$8:$X$1048576) -> 3388880.3 | AI41: =AH41/AG41 -> 0.091105766
...

Sheet Detail1
A1: Details for Sum of HJ Total
A3: Tanggal | B3: Nomor Faktur | C3: SALES | D3: Brand | E3: Divisi | F3: Kuantitas | G3: HJ Total | H3: HB Total | I3: Margin awal | J3: biaya pengiriman | K3: Status | L3: Promo ID | M3: CB Promo | N3: Gathering | O3: Kontrak | P3: 2% | Q3: Margin Akhir
A4: 46235 | B4: SO.AV.2026.08.00001 | C4: SALES002 | D4: ABEM005 | E4: DIV 2 | F4: 2 | G4: 183150 | H4: 129423.57 | I4: 35576.432 | J4: 7254.2609 | K4: NoN Local Promo | L4: Gathering Only | M4: 0 | N4: 3125 | O4: 0 | P4: 3663 | Q4: 21534.172
A5: 46235 | B5: SO.AV.2026.08.00002 | C5: SALES005 | D5: AVSY100 | E5: DIV 1 | F5: 24 | G5: 335405 | H5: 259309.36 | I5: 42857.305 | J5: 2662.9565 | K5: NoN Local Promo | L5: Non Campaign | M5: 0 | N5: 0 | O5: 0 | P5: 6708.1 | Q5: 33486.248
A6: 46235 | B6: SO.AV.2026.08.00002 | C6: SALES005 | D6: AVSY200 | E6: DIV 1 | F6: 36 | G6: 929347.5 | H6: 716914.12 | I6: 120335.88 | J6: 6758.3908 | K6: NoN Local Promo | L6: Non Campaign | M6: 0 | N6: 0 | O6: 0 | P6: 18586.95 | Q6: 94990.54
A7: 46235 | B7: SO.AV.2026.08.00003 | C7: SALES001 | D7: AVSY001 | E7: DIV 1 | F7: 6 | G7: 553890 | H7: 425711.09 | I7: 73288.908 | J7: 5647.3043 | K7: NoN Local Promo | L7: Gathering Only | M7: 0 | N7: 8333.3333 | O7: 0 | P7: 11077.8 | Q7: 48230.47
A8: 46235 | B8: SO.AV.2026.08.00004 | C8: SALES012 | D8: AVSY001 | E8: DIV 1 | F8: 5 | G8: 461575 | H8: 354759.24 | I8: 61074.09 | J8: 4706.087 | K8: NoN Local Promo | L8: Gathering Only | M8: 0 | N8: 7142.8571 | O8: 0 | P8: 9231.5 | Q8: 39993.646
A9: 46235 | B9: SO.AV.2026.08.00006 | C9: SALES001 | D9: AVSY100 | E9: DIV 1 | F9: 12 | G9: 167702.5 | H9: 129654.68 | I9: 21428.652 | J9: 1331.4783 | K9: NoN Local Promo | L9: Gathering Only | M9: 0 | N9: 3333.3333 | O9: 0 | P9: 3354.05 | Q9: 13409.791
A10: 46235 | B10: SO.AV.2026.08.00006 | C10: SALES001 | D10: AVSY500 | E10: DIV 1 | F10: 6 | G10: 315795 | H10: 240358.05 | I10: 44141.946 | J10: 2851.2 | K10: NoN Local Promo | L10: Gathering Only | M10: 0 | N10: 3333.3333 | O10: 0 | P10: 6315.9 | Q10: 31641.513
A11: 46235 | B11: SO.AV.2026.08.00007 | C11: SALES004 | D11: AVSY001 | E11: DIV 1 | F11: 6 | G11: 553890 | H11: 425711.09 | I11: 73288.908 | J11: 5647.3043 | K11: NoN Local Promo | L11: Non Campaign | M11: 0 | N11: 0 | O11: 0 | P11: 11077.8 | Q11: 56563.804
A12: 46235 | B12: SO.AV.2026.08.00008 | C12: SALES004 | D12: NODR001 | E12: DIV 2 | F12: 2 | G12: 152070 | H12: 115402.68 | I12: 21597.319 | J12: 1668.1739 | K12: Kontrak | L12: Contract | M12: 0 | N12: 0 | O12: 6082.8 | P12: 3041.4 | Q12: 10804.945
